Workbook

Sheet Olah Semivariogram
I1: Menghitung jarak antar titik lokasi gempa | AH1: Menentukan semivarian
A2: Data Kekuatan Gempa Bumi Jawa Barat Tahun 2021 | N2: 3.2 | O2: 2.7 | P2: 3.2 | Q2: 3.2 | R2: 2.2 | S2: 3.6 | T2: 3.1 | U2: 3.5 | V2: 4.5 | W2: 2.8 | Z2: zi | AA2: zj | AB2: jarak(h) | AC2: (zi-zj)^2 | AD2: semivarians | AE2: rata-rata | AH2: Offset | AI2: banyak lokasi | AJ2: sigma(zi-zj)^2 | AK2: bin center | AL2: bin range | AN2: semivarians | AP2: spherical | AQ2: exponential | AR2: gaussian | AS2: SE sphr | AT2: SE exp | AU2: SE gau
A3: Lokasi | B3: Tanggal | C3: Jam | D3: Lintang (x) | E3: Bujur (y) | F3: Kedalaman (km) | G3: Magnitudo (R) | I3: Banyak lokasi (n) | J3: =COUNTA(B5:B143) -> 139 | M3: Lokasi | N3: 1 | O3: 2 | P3: 3 | Q3: 4 | R3: 5 | S3: 6 | T3: 7 | U3: 8 | V3: 9 | W3: 10 | Y3: offset 1 | Z3: 3.2 | AA3: 3.2 | AB3: 0 | AC3: =(Z3-AA3)^2 -> 0 | AD3: =AC3/20 -> 0 | AE3: =AVERAGE(AD3:AD19) -> 0.20470588 | AF3: 0.1 | AH3: 1 | AI3: =COUNT(Z3:Z12) -> 10 | AJ3: =SUM(AC3:AC12) -> 0 | AK3: 0 | AL3: 0 | AM3: 0 | AN3: 0 | AP3: 0 | AQ3: 0 | AR3: 0 | AS3: 0 | AT3: 0 | AU3: 0
I4: banyak pasangan data | J4: =(J3*(J3-1))/2 -> 9591 | L4: 3.2 | M4: 1 | N4: =SQRT(('Olah Semivariogram'!$D$5-'Olah Semivariogram'!D5)^2+('Olah Semivariogram'!$E$5-'Olah Semivariogram'!E5)^2) -> 0 | O4: =SQRT(('Olah Semivariogram'!$D$6-'Olah Semivariogram'!D5)^2+('Olah Semivariogram'!$E$6-'Olah Semivariogram'!E5)^2) -> 0.45276926 | P4: =SQRT(('Olah Semivariogram'!$D$7-'Olah Semivariogram'!D5)^2+('Olah Semivariogram'!$E$7-'Olah Semivariogram'!E5)^2) -> 0.72801099 | Q4: =SQRT(('Olah Semivariogram'!$D$8-'Olah Semivariogram'!D5)^2+('Olah Semivariogram'!$E$8-'Olah Semivariogram'!E5)^2) -> 0.65513357 | R4: =SQRT(('Olah Semivariogram'!$D$9-'Olah Semivariogram'!D5)^2+('Olah Semivariogram'!$E$9-'Olah Semivariogram'!E5)^2) -> 0.45276926 | S4: =SQRT(('Olah Semivariogram'!$D$10-'Olah Semivariogram'!D5)^2+('Olah Semivariogram'!$E$10-'Olah Semivariogram'!E5)^2) -> 0.65734314 | T4: =SQRT(('Olah Semivariogram'!$D$11-'Olah Semivariogram'!D5)^2+('Olah Semivariogram'!$E$11-'Olah Semivariogram'!E5)^2) -> 0.13601471 | U4: =SQRT(('Olah Semivariogram'!$D$12-'Olah Semivariogram'!D5)^2+('Olah Semivariogram'!$E$12-'Olah Semivariogram'!E5)^2) -> 0.33837849 | V4: =SQRT(('Olah Semivariogram'!$D$13-'Olah Semivariogram'!D5)^2+('Olah Semivariogram'!$E$13-'Olah Semivariogram'!E5)^2) -> 0.09963935 | W4: =SQRT(('Olah Semivariogram'!$D$14-'Olah Semivariogram'!D5)^2+('Olah Semivariogram'!$E$14-'Olah Semivariogram'!E5)^2) -> 0.08 | Z4: 2.7 | AA4: 2.7 | AB4: 0 | AC4: =(Z4-AA4)^2 -> 0 | AD4: =AC4/20 -> 0 | AH4: 2 | AI4: =COUNT(Z13:Z18) -> 6 | AJ4: =SUM(AC13:AC18) -> 6.87 | AK4: =MEDIAN(AL4,AM4) -> 0.11996399 | AL4: 0.059981993 | AM4: 0.17994598 | AN4: =AJ4/(2*AI4) -> 0.5725 | AP4: =$AN$14*(1.5*(AK4/$AN$15)-0.5*(AK4/$AN$15)^3) -> 0.17473724 | AQ4: =$AN$14*(1-EXP(-(AK4/$AN$15))) -> 0.10416208 | AR4: =$AN$14*(1-EXP(-((AK4)^2/($AN$15)^2))) -> 0.032855021 | AS4: =(AP4-AN4)^2 -> 0.15821521 | AT4: =(AQ4-AN4)^2 -> 0.21934041 | AU4: =(AR4-AN4)^2 -> 0.2912167
A5: 1 | B5: 44201 | C5: 0.98804398 | D5: -7.47 | E5: 106.71 | F5: 36 | G5: 3.2 | L5: 2.7 | M5: 2 | N5: =SQRT(('Olah Semivariogram'!$D$5-'Olah Semivariogram'!D6)^2+('Olah Semivariogram'!$E$5-'Olah Semivariogram'!E6)^2) -> 0.45276926 | O5: =SQRT(('Olah Semivariogram'!$D$6-'Olah Semivariogram'!D6)^2+('Olah Semivariogram'!$E$6-'Olah Semivariogram'!E6)^2) -> 0 | P5: =SQRT(('Olah Semivariogram'!$D$7-'Olah Semivariogram'!D6)^2+('Olah Semivariogram'!$E$7-'Olah Semivariogram'!E6)^2) -> 0.35355339 | Q5: =SQRT(('Olah Semivariogram'!$D$8-'Olah Semivariogram'!D6)^2+('Olah Semivariogram'!$E$8-'Olah Semivariogram'!E6)^2) -> 0.71512237 | R5: =SQRT(('Olah Semivariogram'!$D$9-'Olah Semivariogram'!D6)^2+('Olah Semivariogram'!$E$9-'Olah Semivariogram'!E6)^2) -> 0.28635642 | S5: =SQRT(('Olah Semivariogram'!$D$10-'Olah Semivariogram'!D6)^2+('Olah Semivariogram'!$E$10-'Olah Semivariogram'!E6)^2) -> 0.73054774 | T5: =SQRT(('Olah Semivariogram'!$D$11-'Olah Semivariogram'!D6)^2+('Olah Semivariogram'!$E$11-'Olah Semivariogram'!E6)^2) -> 0.44777226 | U5: =SQRT(('Olah Semivariogram'!$D$12-'Olah Semivariogram'!D6)^2+('Olah Semivariogram'!$E$12-'Olah Semivariogram'!E6)^2) -> 0.78873316 | V5: =SQRT(('Olah Semivariogram'!$D$13-'Olah Semivariogram'!D6)^2+('Olah Semivariogram'!$E$13-'Olah Semivariogram'!E6)^2) -> 0.40175614 | W5: =SQRT(('Olah Semivariogram'!$D$14-'Olah Semivariogram'!D6)^2+('Olah Semivariogram'!$E$14-'Olah Semivariogram'!E6)^2) -> 0.40224371 | Z5: 3.2 | AA5: 3.2 | AB5: 0 | AC5: =(Z5-AA5)^2 -> 0 | AD5: =AC5/20 -> 0 | AH5: 3 | AI5: =COUNTA(Z19:Z20) -> 2 | AJ5: =SUM(AC19:AC20) -> 0.34 | AK5: =MEDIAN(AL5,AM5) -> 0.23992797 | AL5: 0.17994598 | AM5: 0.29990997 | AN5: =AJ5/(2*AI5) -> 0.085 | AP5: =$AN$14*(1.5*(AK5/$AN$15)-0.5*(AK5/$AN$15)^3) -> 0.32014796 | AQ5: =$AN$14*(1-EXP(-(AK5/$AN$15))) -> 0.18243752 | AR5: =$AN$14*(1-EXP(-((AK5)^2/($AN$15)^2))) -> 0.11675888 | AS5: =(AP5-AN5)^2 -> 0.055294563 | AT5: =(AQ5-AN5)^2 -> 0.0094940697 | AU5: =(AR5-AN5)^2 -> 0.0010086266
A6: 2 | B6: 44203 | C6: 0.30513889 | D6: -7.14 | E6: 107.02 | F6: 81 | G6: 2.7 | L6: 3.2 | M6: 3 | N6: =SQRT(('Olah Semivariogram'!$D$5-'Olah Semivariogram'!D7)^2+('Olah Semivariogram'!$E$5-'Olah Semivariogram'!E7)^2) -> 0.72801099 | O6: =SQRT(('Olah Semivariogram'!$D$6-'Olah Semivariogram'!D7)^2+('Olah Semivariogram'!$E$6-'Olah Semivariogram'!E7)^2) -> 0.35355339 | P6: =SQRT(('Olah Semivariogram'!$D$7-'Olah Semivariogram'!D7)^2+('Olah Semivariogram'!$E$7-'Olah Semivariogram'!E7)^2) -> 0 | Q6: =SQRT(('Olah Semivariogram'!$D$8-'Olah Semivariogram'!D7)^2+('Olah Semivariogram'!$E$8-'Olah Semivariogram'!E7)^2) -> 1.0632027 | R6: =SQRT(('Olah Semivariogram'!$D$9-'Olah Semivariogram'!D7)^2+('Olah Semivariogram'!$E$9-'Olah Semivariogram'!E7)^2) -> 0.31144823 | S6: =SQRT(('Olah Semivariogram'!$D$10-'Olah Semivariogram'!D7)^2+('Olah Semivariogram'!$E$10-'Olah Semivariogram'!E7)^2) -> 1.0796759 | T6: =SQRT(('Olah Semivariogram'!$D$11-'Olah Semivariogram'!D7)^2+('Olah Semivariogram'!$E$11-'Olah Semivariogram'!E7)^2) -> 0.66370174 | U6: =SQRT(('Olah Semivariogram'!$D$12-'Olah Semivariogram'!D7)^2+('Olah Semivariogram'!$E$12-'Olah Semivariogram'!E7)^2) -> 1.0602358 | V6: =SQRT(('Olah Semivariogram'!$D$13-'Olah Semivariogram'!D7)^2+('Olah Semivariogram'!$E$13-'Olah Semivariogram'!E7)^2) -> 0.64498682 | W6: =SQRT(('Olah Semivariogram'!$D$14-'Olah Semivariogram'!D7)^2+('Olah Semivariogram'!$E$14-'Olah Semivariogram'!E7)^2) -> 0.70342022 | Z6: 3.2 | AA6: 3.2 | AB6: 0 | AC6: =(Z6-AA6)^2 -> 0 | AD6: =AC6/20 -> 0 | AH6: 4 | AI6: =COUNT(Z21:Z30) -> 10 | AJ6: =SUM(AC21:AC30) -> 12.34 | AK6: =MEDIAN(AL6,AM6) -> 0.35989196 | AL6: 0.29990997 | AM6: 0.41987395 | AN6: =AJ6/(2*AI6) -> 0.617 | AP6: =$AN$14*(1.5*(AK6/$AN$15)-0.5*(AK6/$AN$15)^3) -> 0.40690561 | AQ6: =$AN$14*(1-EXP(-(AK6/$AN$15))) -> 0.24125973 | AR6: =$AN$14*(1-EXP(-((AK6)^2/($AN$15)^2))) -> 0.21809074 | AS6: =(AP6-AN6)^2 -> 0.044139652 | AT6: =(AQ6-AN6)^2 -> 0.14118075 | AU6: =(AR6-AN6)^2 -> 0.1591286
A7: 3 | B7: 44207 | C7: 0.52436343 | D7: -6.79 | E7: 106.97 | F7: 10 | G7: 3.2 | I7: percobaan | L7: 3.2 | M7: 4 | N7: =SQRT(('Olah Semivariogram'!$D$5-'Olah Semivariogram'!D8)^2+('Olah Semivariogram'!$E$5-'Olah Semivariogram'!E8)^2) -> 0.65513357 | O7: =SQRT(('Olah Semivariogram'!$D$6-'Olah Semivariogram'!D8)^2+('Olah Semivariogram'!$E$6-'Olah Semivariogram'!E8)^2) -> 0.71512237 | P7: =SQRT(('Olah Semivariogram'!$D$7-'Olah Semivariogram'!D8)^2+('Olah Semivariogram'!$E$7-'Olah Semivariogram'!E8)^2) -> 1.0632027 | Q7: =SQRT(('Olah Semivariogram'!$D$8-'Olah Semivariogram'!D8)^2+('Olah Semivariogram'!$E$8-'Olah Semivariogram'!E8)^2) -> 0 | R7: =SQRT(('Olah Semivariogram'!$D$9-'Olah Semivariogram'!D8)^2+('Olah Semivariogram'!$E$9-'Olah Semivariogram'!E8)^2) -> 0.94031909 | S7: =SQRT(('Olah Semivariogram'!$D$10-'Olah Semivariogram'!D8)^2+('Olah Semivariogram'!$E$10-'Olah Semivariogram'!E8)^2) -> 0.02236068 | T7: =SQRT(('Olah Semivariogram'!$D$11-'Olah Semivariogram'!D8)^2+('Olah Semivariogram'!$E$11-'Olah Semivariogram'!E8)^2) -> 0.7823682 | U7: =SQRT(('Olah Semivariogram'!$D$12-'Olah Semivariogram'!D8)^2+('Olah Semivariogram'!$E$12-'Olah Semivariogram'!E8)^2) -> 0.75239617 | V7: =SQRT(('Olah Semivariogram'!$D$13-'Olah Semivariogram'!D8)^2+('Olah Semivariogram'!$E$13-'Olah Semivariogram'!E8)^2) -> 0.72520894 | W7: =SQRT(('Olah Semivariogram'!$D$14-'Olah Semivariogram'!D8)^2+('Olah Semivariogram'!$E$14-'Olah Semivariogram'!E8)^2) -> 0.58821765 | Z7: 2.2 | AA7: 2.2 | AB7: 0 | AC7: =(Z7-AA7)^2 -> 0 | AD7: =AC7/20 -> 0 | AH7: 5 | AI7: =COUNT(Z31:Z34) -> 4 | AJ7: =SUM(AC31:AC34) -> 1.77 | AK7: =MEDIAN(AL7,AM7) -> 0.47985595 | AL7: 0.41987395 | AM7: 0.53983794 | AN7: =AJ7/(2*AI7) -> 0.22125 | AP7: =$AN$14 -> 0.419125 | AQ7: =$AN$14*(1-EXP(-(AK7/$AN$15))) -> 0.28546329 | AR7: =$AN$14*(1-EXP(-((AK7)^2/($AN$15)^2))) -> 0.30559731 | AS7: =(AP7-AN7)^2 -> 0.039154516 | AT7: =(AQ7-AN7)^2 -> 0.0041233465 | AU7: =(AR7-AN7)^2 -> 0.007114469
A8: 4 | B8: 44215 | C8: 0.6603588 | D8: -7.81 | E8: 107.27 | F8: 30 | G8: 3.2 | I8: Banyak lokasi (n) | J8: 10 | L8: 2.2 | M8: 5 | N8: =SQRT(('Olah Semivariogram'!$D$5-'Olah Semivariogram'!D9)^2+('Olah Semivariogram'!$E$5-'Olah Semivariogram'!E9)^2) -> 0.45276926 | O8: =SQRT(('Olah Semivariogram'!$D$6-'Olah Semivariogram'!D9)^2+('Olah Semivariogram'!$E$6-'Olah Semivariogram'!E9)^2) -> 0.28635642 | P8: =SQRT(('Olah Semivariogram'!$D$7-'Olah Semivariogram'!D9)^2+('Olah Semivariogram'!$E$7-'Olah Semivariogram'!E9)^2) -> 0.31144823 | Q8: =SQRT(('Olah Semivariogram'!$D$8-'Olah Semivariogram'!D9)^2+('Olah Semivariogram'!$E$8-'Olah Semivariogram'!E9)^2) -> 0.94031909 | R8: =SQRT(('Olah Semivariogram'!$D$9-'Olah Semivariogram'!D9)^2+('Olah Semivariogram'!$E$9-'Olah Semivariogram'!E9)^2) -> 0 | S8: =SQRT(('Olah Semivariogram'!$D$10-'Olah Semivariogram'!D9)^2+('Olah Semivariogram'!$E$10-'Olah Semivariogram'!E9)^2) -> 0.95189285 | T8: =SQRT(('Olah Semivariogram'!$D$11-'Olah Semivariogram'!D9)^2+('Olah Semivariogram'!$E$11-'Olah Semivariogram'!E9)^2) -> 0.36400549 | U8: =SQRT(('Olah Semivariogram'!$D$12-'Olah Semivariogram'!D9)^2+('Olah Semivariogram'!$E$12-'Olah Semivariogram'!E9)^2) -> 0.76843998 | V8: =SQRT(('Olah Semivariogram'!$D$13-'Olah Semivariogram'!D9)^2+('Olah Semivariogram'!$E$13-'Olah Semivariogram'!E9)^2) -> 0.35850802 | W8: =SQRT(('Olah Semivariogram'!$D$14-'Olah Semivariogram'!D9)^2+('Olah Semivariogram'!$E$14-'Olah Semivariogram'!E9)^2) -> 0.45099889 | Z8: 3.6 | AA8: 3.6 | AB8: 0 | AC8: =(Z8-AA8)^2 -> 0 | AD8: =AC8/20 -> 0 | AH8: 6 | AI8: =COUNT(Z35:Z39) -> 5 | AJ8: =SUM(AC35:AC39) -> 2.65 | AK8: =MEDIAN(AL8,AM8) -> 0.59981993 | AL8: 0.53983794 | AM8: 0.65980193 | AN8: =AJ8/(2*AI8) -> 0.265 | AP8: =$AN$14 -> 0.419125 | AQ8: =$AN$14*(1-EXP(-(AK8/$AN$15))) -> 0.31868126 | AR8: =$AN$14*(1-EXP(-((AK8)^2/($AN$15)^2))) -> 0.36467119 | AS8: =(AP8-AN8)^2 -> 0.023754516 | AT8: =(AQ8-AN8)^2 -> 0.0028816776 | AU8: =(AR8-AN8)^2 -> 0.0099343455
A9: 5 | B9: 44215 | C9: 0.67125 | D9: -7.02 | E9: 106.76 | F9: 10 | G9: 2.2 | I9: banyak pasangan lokasi | J9: =(J8*(J8-1))/2 -> 45 | L9: 3.6 | M9: 6 | N9: =SQRT(('Olah Semivariogram'!$D$5-'Olah Semivariogram'!D10)^2+('Olah Semivariogram'!$E$5-'Olah Semivariogram'!E10)^2) -> 0.65734314 | O9: =SQRT(('Olah Semivariogram'!$D$6-'Olah Semivariogram'!D10)^2+('Olah Semivariogram'!$E$6-'Olah Semivariogram'!E10)^2) -> 0.73054774 | P9: =SQRT(('Olah Semivariogram'!$D$7-'Olah Semivariogram'!D10)^2+('Olah Semivariogram'!$E$7-'Olah Semivariogram'!E10)^2) -> 1.0796759 | Q9: =SQRT(('Olah Semivariogram'!$D$8-'Olah Semivariogram'!D10)^2+('Olah Semivariogram'!$E$8-'Olah Semivariogram'!E10)^2) -> 0.02236068 | R9: =SQRT(('Olah Semivariogram'!$D$9-'Olah Semivariogram'!D10)^2+('Olah Semivariogram'!$E$9-'Olah Semivariogram'!E10)^2) -> 0.95189285 | S9: =SQRT(('Olah Semivariogram'!$D$10-'Olah Semivariogram'!D10)^2+('Olah Semivariogram'!$E$10-'Olah Semivariogram'!E10)^2) -> 0 | T9: =SQRT(('Olah Semivariogram'!$D$11-'Olah Semivariogram'!D10)^2+('Olah Semivariogram'!$E$11-'Olah Semivariogram'!E10)^2) -> 0.78600254 | U9: =SQRT(('Olah Semivariogram'!$D$12-'Olah Semivariogram'!D10)^2+('Olah Semivariogram'!$E$12-'Olah Semivariogram'!E10)^2) -> 0.74431176 | V9: =SQRT(('Olah Semivariogram'!$D$13-'Olah Semivariogram'!D10)^2+('Olah Semivariogram'!$E$13-'Olah Semivariogram'!E10)^2) -> 0.72964923 | W9: =SQRT(('Olah Semivariogram'!$D$14-'Olah Semivariogram'!D10)^2+('Olah Semivariogram'!$E$14-'Olah Semivariogram'!E10)^2) -> 0.5920304 | Z9: 3.1 | AA9: 3.1 | AB9: 0 | AC9: =(Z9-AA9)^2 -> 0 | AD9: =AC9/20 -> 0 | AH9: 7 | AI9: =COUNT(Z40:Z49) -> 10 | AJ9: =SUM(AC40:AC49) -> 5.52 | AK9: =MEDIAN(AL9,AM9) -> 0.71978392 | AL9: 0.65980193 | AM9: 0.77976591 | AN9: =AJ9/(2*AI9) -> 0.276 | AP9: =$AN$14 -> 0.419125 | AQ9: =$AN$14*(1-EXP(-(AK9/$AN$15))) -> 0.34364381 | AR9: =$AN$14*(1-EXP(-((AK9)^2/($AN$15)^2))) -> 0.3969405 | AS9: =(AP9-AN9)^2 -> 0.020484766 | AT9: =(AQ9-AN9)^2 -> 0.004575685 | AU9: =(AR9-AN9)^2 -> 0.014626605
A10: 6 | B10: 44216 | C10: 0.88252315 | D10: -7.83 | E10: 107.26 | F10: 27 | G10: 3.6 | L10: 3.1 | M10: 7 | N10: =SQRT(('Olah Semivariogram'!$D$5-'Olah Semivariogram'!D11)^2+('Olah Semivariogram'!$E$5-'Olah Semivariogram'!E11)^2) -> 0.13601471 | O10: =SQRT(('Olah Semivariogram'!$D$6-'Olah Semivariogram'!D11)^2+('Olah Semivariogram'!$E$6-'Olah Semivariogram'!E11)^2) -> 0.44777226 | P10: =SQRT(('Olah Semivariogram'!$D$7-'Olah Semivariogram'!D11)^2+('Olah Semivariogram'!$E$7-'Olah Semivariogram'!E11)^2) -> 0.66370174 | Q10: =SQRT(('Olah Semivariogram'!$D$8-'Olah Semivariogram'!D11)^2+('Olah Semivariogram'!$E$8-'Olah Semivariogram'!E11)^2) -> 0.7823682 | R10: =SQRT(('Olah Semivariogram'!$D$9-'Olah Semivariogram'!D11)^2+('Olah Semivariogram'!$E$9-'Olah Semivariogram'!E11)^2) -> 0.36400549 | S10: =SQRT(('Olah Semivariogram'!$D$10-'Olah Semivariogram'!D11)^2+('Olah Semivariogram'!$E$10-'Olah Semivariogram'!E11)^2) -> 0.78600254 | T10: =SQRT(('Olah Semivariogram'!$D$11-'Olah Semivariogram'!D11)^2+('Olah Semivariogram'!$E$11-'Olah Semivariogram'!E11)^2) -> 0 | U10: =SQRT(('Olah Semivariogram'!$D$12-'Olah Semivariogram'!D11)^2+('Olah Semivariogram'!$E$12-'Olah Semivariogram'!E11)^2) -> 0.40521599 | V10: =SQRT(('Olah Semivariogram'!$D$13-'Olah Semivariogram'!D11)^2+('Olah Semivariogram'!$E$13-'Olah Semivariogram'!E11)^2) -> 0.063150614 | W10: =SQRT(('Olah Semivariogram'!$D$14-'Olah Semivariogram'!D11)^2+('Olah Semivariogram'!$E$14-'Olah Semivariogram'!E11)^2) -> 0.19416488 | Z10: 3.5 | AA10: 3.5 | AB10: 0 | AC10: =(Z10-AA10)^2 -> 0 | AD10: =AC10/20 -> 0 | AH10: 8 | AI10: =COUNT(Z50:Z52) -> 3 | AJ10: =SUM(AC50:AC52) -> 0.9 | AK10: =MEDIAN(AL10,AM10) -> 0.8397479 | AL10: 0.77976591 | AM10: 0.8997299 | AN10: =AJ10/(2*AI10) -> 0.15 | AP10: =$AN$14 -> 0.419125 | AQ10: =$AN$14*(1-EXP(-(AK10/$AN$15))) -> 0.3624026 | AR10: =$AN$14*(1-EXP(-((AK10)^2/($AN$15)^2))) -> 0.41144846 | AS10: =(AP10-AN10)^2 -> 0.072428266 | AT10: =(AQ10-AN10)^2 -> 0.045114864 | AU10: =(AR10-AN10)^2 -> 0.068355296
A11: 7 | B11: 44221 | C11: 0.65237269 | D11: -7.36 | E11: 106.63 | F11: 81 | G11: 3.1 | I11: Menghitung Jarak Euclidean | L11: 3.5 | M11: 8 | N11: =SQRT(('Olah Semivariogram'!$D$5-'Olah Semivariogram'!D12)^2+('Olah Semivariogram'!$E$5-'Olah Semivariogram'!E12)^2) -> 0.33837849 | O11: =SQRT(('Olah Semivariogram'!$D$6-'Olah Semivariogram'!D12)^2+('Olah Semivariogram'!$E$6-'Olah Semivariogram'!E12)^2) -> 0.78873316 | P11: =SQRT(('Olah Semivariogram'!$D$7-'Olah Semivariogram'!D12)^2+('Olah Semivariogram'!$E$7-'Olah Semivariogram'!E12)^2) -> 1.0602358 | Q11: =SQRT(('Olah Semivariogram'!$D$8-'Olah Semivariogram'!D12)^2+('Olah Semivariogram'!$E$8-'Olah Semivariogram'!E12)^2) -> 0.75239617 | R11: =SQRT(('Olah Semivariogram'!$D$9-'Olah Semivariogram'!D12)^2+('Olah Semivariogram'!$E$9-'Olah Semivariogram'!E12)^2) -> 0.76843998 | S11: =SQRT(('Olah Semivariogram'!$D$10-'Olah Semivariogram'!D12)^2+('Olah Semivariogram'!$E$10-'Olah Semivariogram'!E12)^2) -> 0.74431176 | T11: =SQRT(('Olah Semivariogram'!$D$11-'Olah Semivariogram'!D12)^2+('Olah Semivariogram'!$E$11-'Olah Semivariogram'!E12)^2) -> 0.40521599 | U11: =SQRT(('Olah Semivariogram'!$D$12-'Olah Semivariogram'!D12)^2+('Olah Semivariogram'!$E$12-'Olah Semivariogram'!E12)^2) -> 0 | V11: =SQRT(('Olah Semivariogram'!$D$13-'Olah Semivariogram'!D12)^2+('Olah Semivariogram'!$E$13-'Olah Semivariogram'!E12)^2) -> 0.41529267 | W11: =SQRT(('Olah Semivariogram'!$D$14-'Olah Semivariogram'!D12)^2+('Olah Semivariogram'!$E$14-'Olah Semivariogram'!E12)^2) -> 0.38897301 | Z11: 4.5 | AA11: 4.5 | AB11: 0 | AC11: =(Z11-AA11)^2 -> 0 | AD11: =AC11/20 -> 0 | AH11: 9 | AI11: =COUNT(Z53:Z54) -> 2 | AJ11: =SUM(AC53:AC54) -> 2.96 | AK11: =MEDIAN(AL11,AM11) -> 0.95971189 | AL11: 0.8997299 | AM11: 1.0196939 | AN11: =AJ11/(2*AI11) -> 0.74 | AP11: =$AN$14 -> 0.419125 | AQ11: =$AN$14*(1-EXP(-(AK11/$AN$15))) -> 0.3764994 | AR11: =$AN$14*(1-EXP(-((AK11)^2/($AN$15)^2))) -> 0.41686881 | AS11: =(AP11-AN11)^2 -> 0.10296077 | AT11: =(AQ11-AN11)^2 -> 0.13213268 | AU11: =(AR11-AN11)^2 -> 0.10441377
A12: 8 | B12: 44247 | C12: 0.38552083 | D12: -7.75 | E12: 106.52 | F12: 20 | G12: 3.5 | L12: 4.5 | M12: 9 | N12: =SQRT(('Olah Semivariogram'!$D$5-'Olah Semivariogram'!D13)^2+('Olah Semivariogram'!$E$5-'Olah Semivariogram'!E13)^2) -> 0.09963935 | O12: =SQRT(('Olah Semivariogram'!$D$6-'Olah Semivariogram'!D13)^2+('Olah Semivariogram'!$E$6-'Olah Semivariogram'!E13)^2) -> 0.40175614 | P12: =SQRT(('Olah Semivariogram'!$D$7-'Olah Semivariogram'!D13)^2+('Olah Semivariogram'!$E$7-'Olah Semivariogram'!E13)^2) -> 0.64498682 | Q12: =SQRT(('Olah Semivariogram'!$D$8-'Olah Semivariogram'!D13)^2+('Olah Semivariogram'!$E$8-'Olah Semivariogram'!E13)^2) -> 0.72520894 | R12: =SQRT(('Olah Semivariogram'!$D$9-'Olah Semivariogram'!D13)^2+('Olah Semivariogram'!$E$9-'Olah Semivariogram'!E13)^2) -> 0.35850802 | S12: =SQRT(('Olah Semivariogram'!$D$10-'Olah Semivariogram'!D13)^2+('Olah Semivariogram'!$E$10-'Olah Semivariogram'!E13)^2) -> 0.72964923 | T12: =SQRT(('Olah Semivariogram'!$D$11-'Olah Semivariogram'!D13)^2+('Olah Semivariogram'!$E$11-'Olah Semivariogram'!E13)^2) -> 0.063150614 | U12: =SQRT(('Olah Semivariogram'!$D$12-'Olah Semivariogram'!D13)^2+('Olah Semivariogram'!$E$12-'Olah Semivariogram'!E13)^2) -> 0.41529267 | V12: =SQRT(('Olah Semivariogram'!$D$13-'Olah Semivariogram'!D13)^2+('Olah Semivariogram'!$E$13-'Olah Semivariogram'!E13)^2) -> 0 | W12: =SQRT(('Olah Semivariogram'!$D$14-'Olah Semivariogram'!D13)^2+('Olah Semivariogram'!$E$14-'Olah Semivariogram'!E13)^2) -> 0.13859293 | Z12: 2.8 | AA12: 2.8 | AB12: 0 | AC12: =(Z12-AA12)^2 -> 0 | AD12: =AC12/20 -> 0 | AH12: 10 | AI12: =COUNT(Z55:Z57) -> 3 | AJ12: =SUM(AC55:AC57) -> 0.25 | AK12: =MEDIAN(AL12,AM12) -> 1.0796759 | AL12: 1.0196939 | AM12: 1.1396579 | AN12: =AJ12/(2*AI12) -> 0.041666667 | AP12: =$AN$14 -> 0.419125 | AQ12: =$AN$14*(1-EXP(-(AK12/$AN$15))) -> 0.38709283 | AR12: =$AN$14*(1-EXP(-((AK12)^2/($AN$15)^2))) -> 0.41856177 | AS12: =(AP12-AN12)^2 -> 0.14247479 | AT12: =(AQ12-AN12)^2 -> 0.11931924 | AU12: =(AR12-AN12)^2 -> 0.14204992
A13: 9 | B13: 44248 | C13: 0.62260417 | D13: -7.372 | E13: 106.692 | F13: 60 | G13: 4.5 | L13: 2.8 | M13: 10 | N13: =SQRT(('Olah Semivariogram'!$D$5-'Olah Semivariogram'!D14)^2+('Olah Semivariogram'!$E$5-'Olah Semivariogram'!E14)^2) -> 0.08 | O13: =SQRT(('Olah Semivariogram'!$D$6-'Olah Semivariogram'!D14)^2+('Olah Semivariogram'!$E$6-'Olah Semivariogram'!E14)^2) -> 0.40224371 | P13: =SQRT(('Olah Semivariogram'!$D$7-'Olah Semivariogram'!D14)^2+('Olah Semivariogram'!$E$7-'Olah Semivariogram'!E14)^2) -> 0.70342022 | Q13: =SQRT(('Olah Semivariogram'!$D$8-'Olah Semivariogram'!D14)^2+('Olah Semivariogram'!$E$8-'Olah Semivariogram'!E14)^2) -> 0.58821765 | R13: =SQRT(('Olah Semivariogram'!$D$9-'Olah Semivariogram'!D14)^2+('Olah Semivariogram'!$E$9-'Olah Semivariogram'!E14)^2) -> 0.45099889 | S13: =SQRT(('Olah Semivariogram'!$D$10-'Olah Semivariogram'!D14)^2+('Olah Semivariogram'!$E$10-'Olah Semivariogram'!E14)^2) -> 0.5920304 | T13: =SQRT(('Olah Semivariogram'!$D$11-'Olah Semivariogram'!D14)^2+('Olah Semivariogram'!$E$11-'Olah Semivariogram'!E14)^2) -> 0.19416488 | U13: =SQRT(('Olah Semivariogram'!$D$12-'Olah Semivariogram'!D14)^2+('Olah Semivariogram'!$E$12-'Olah Semivariogram'!E14)^2) -> 0.38897301 | V13: =SQRT(('Olah Semivariogram'!$D$13-'Olah Semivariogram'!D14)^2+('Olah Semivariogram'!$E$13-'Olah Semivariogram'!E14)^2) -> 0.13859293 | W13: =SQRT(('Olah Semivariogram'!$D$14-'Olah Semivariogram'!D14)^2+('Olah Semivariogram'!$E$14-'Olah Semivariogram'!E14)^2) -> 0 | Y13: offset 2 | Z13: 3.2 | AA13: 3.6 | AB13: 0.02236068 | AC13: =(Z13-AA13)^2 -> 0.16 | AD13: =AC13/2 -> 0.08 | AM13: nugget (C0) | AN13: 0 | AP13: 0 | AQ13: 0 | AR13: 0 | AS13: =AVERAGE(AS3:AS12) -> 0.065890705 | AT13: =AVERAGE(AT3:AT12) -> 0.067816272 | AU13: =AVERAGE(AU3:AU12) -> 0.079784833 | AV13: MSE
A14: 10 | B14: 44248 | C14: 0.9655787 | D14: -7.47 | E14: 106.79 | F14: 37 | G14: 2.8 | Z14: 3.1 | AA14: 4.5 | AB14: 0.063150614 | AC14: =(Z14-AA14)^2 -> 1.96 | AD14: =AC14/2 -> 0.98 | AM14: sill ( C ) | AN14: =AVERAGE(AN6:AN7) -> 0.419125 | AP14: =AP7 -> 0.419125 | AQ14: =AQ10 -> 0.3624026 | AR14: =AR10 -> 0.41144846 | AS14: =SQRT(AS13) -> 0.25669185 | AT14: =SQRT(AT13) -> 0.26041558 | AU14: =SQRT(AU13) -> 0.28246209 | AV14: RMSE
A15: 11 | B15: 44253 | C15: 0.14162037 | D15: -7.34 | E15: 106.58 | F15: 91 | G15: 2.9 | M15: min | N15: 0 | P15: mean | Q15: =AVERAGE(J5:J14) -> 27.5 | Z15: 3.2 | AA15: 2.8 | AB15: 0.08 | AC15: =(Z15-AA15)^2 -> 0.16 | AD15: =AC15/2 -> 0.08 | AH15: Semivarogram Eksperimental | AM15: range (a) | AN15: =MEDIAN(AK6:AK7) -> 0.41987395 | AP15: =AK7 -> 0.47985595 | AQ15: =AK10 -> 0.8397479 | AR15: =AK10 -> 0.8397479 | AS15: =SUM(AS3:AS12) -> 0.65890705 | AT15: =SUM(AT3:AT12) -> 0.67816272 | AU15: =SUM(AU3:AU12) -> 0.79784833 | AV15: SSE
A16: 12 | B16: 44257 | C16: 0.52834491 | D16: -7.82 | E16: 106.81 | F16: 10 | G16: 3.9 | M16: max | N16: =MAX(N4:W13) -> 1.0796759 | Z16: 3.2 | AA16: 4.5 | AB16: 0.09963935 | AC16: =(Z16-AA16)^2 -> 1.69 | AD16: =AC16/2 -> 0.845
A17: 13 | B17: 44265 | C17: 0.171875 | D17: -6.008 | E17: 107.117 | F17: 310 | G17: 4.1 | Z17: 3.2 | AA17: 3.1 | AB17: 0.13601471 | AC17: =(Z17-AA17)^2 -> 0.01 | AD17: =AC17/2 -> 0.005
A18: 14 | B18: 44274 | C18: 0.7412963 | D18: -7.78 | E18: 106.97 | F18: 25 | G18: 3.1 | M18: Binning data | Z18: 4.5 | AA18: 2.8 | AB18: 0.13859293 | AC18: =(Z18-AA18)^2 -> 2.89 | AD18: =AC18/2 -> 1.445
A19: 15 | B19: 44274 | C19: 0.22549769 | D19: -7.73 | E19: 106.92 | F19: 25 | G19: 2.8 | N19: h= (max/offset-1)*(no offset-1) | Y19: offset 3 | Z19: 3.1 | AA19: 2.8 | AB19: 0.19416488 | AC19: =(Z19-AA19)^2 -> 0.09 | AD19: =AC19/2 -> 0.045
A20: 16 | B20: 44275 | C20: 0.75657407 | D20: -7.82 | E20: 107.26 | F20: 23 | G20: 4.1 | N20: h | O20: delta(h) | P20: h-(detla(h)/2) | Q20: h+(detla(h)/2) | Z20: 2.7 | AA20: 2.2 | AB20: 0.28635642 | AC20: =(Z20-AA20)^2 -> 0.25 | AD20: =AC20/2 -> 0.125 | AE20: =AVERAGE(AB20:AB26) -> 0.34303186 | AF20: 0.3
A21: 17 | B21: 44276 | C21: 0.28738426 | D21: -7.73 | E21: 106.95 | F21: 28 | G21: 2.9 | M21: 1 | N21: 0 | O21: 0 | P21: 0 | Q21: 0 | Y21: offset 4 | Z21: 3.2 | AA21: 2.2 | AB21: 0.31144823 | AC21: =(Z21-AA21)^2 -> 1 | AD21: =AC21/2 -> 0.5
A22: 18 | B22: 44280 | C22: 0.68299769 | D22: -7.84 | E22: 107.27 | F22: 28 | G22: 3.4 | M22: 2 | N22: =($N$16/(10-$M$21))*(M22-$M$21) -> 0.11996399 | O22: =N22-N21 -> 0.11996399 | P22: =N22-(O22/2) -> 0.059981993 | Q22: =N22+(O22/2) -> 0.17994598 | Z22: 3.2 | AA22: 3.5 | AB22: 0.33837849 | AC22: =(Z22-AA22)^2 -> 0.09 | AD22: =AC22/2 -> 0.045
A23: 19 | B23: 44281 | C23: 0.64665509 | D23: -7.11 | E23: 107.42 | F23: 10 | G23: 2.7 | M23: 3 | N23: =($N$16/(10-$M$21))*(M23-$M$21) -> 0.23992797 | O23: =N23-N22 -> 0.11996399 | P23: =N23-(O23/2) -> 0.17994598 | Q23: =N23+(O23/2) -> 0.29990997 | Z23: 2.7 | AA23: 3.2 | AB23: 0.35355339 | AC23: =(Z23-AA23)^2 -> 0.25 | AD23: =AC23/2 -> 0.125 | AH23: Semivariogram spherical
A24: 20 | B24: 44281 | C24: 0.13204861 | D24: -7.59 | E24: 106.77 | F24: 35 | G24: 2.8 | M24: 4 | N24: =($N$16/(10-$M$21))*(M24-$M$21) -> 0.35989196 | O24: =N24-N23 -> 0.11996399 | P24: =N24-(O24/2) -> 0.29990997 | Q24: =N24+(O24/2) -> 0.41987395 | Z24: 2.2 | AA24: 4.5 | AB24: 0.35850802 | AC24: =(Z24-AA24)^2 -> 5.29 | AD24: =AC24/2 -> 2.645
A25: 21 | B25: 44284 | C25: 0.69548611 | D25: -7.48 | E25: 106.73 | F25: 34 | G25: 2.9 | M25: 5 | N25: =($N$16/(10-$M$21))*(M25-$M$21) -> 0.47985595 | O25: =N25-N24 -> 0.11996399 | P25: =N25-(O25/2) -> 0.41987395 | Q25: =N25+(O25/2) -> 0.53983794 | Z25: 2.2 | AA25: 3.1 | AB25: 0.36400549 | AC25: =(Z25-AA25)^2 -> 0.81 | AD25: =AC25/2 -> 0.405
A26: 22 | B26: 44285 | C26: 0.54890046 | D26: -7.69 | E26: 106.59 | F26: 28 | G26: 2.8 | M26: 6 | N26: =($N$16/(10-$M$21))*(M26-$M$21) -> 0.59981993 | O26: =N26-N25 -> 0.11996399 | P26: =N26-(O26/2) -> 0.53983794 | Q26: =N26+(O26/2) -> 0.65980193 | Z26: 3.5 | AA26: 2.8 | AB26: 0.38897301 | AC26: =(Z26-AA26)^2 -> 0.49 | AD26: =AC26/2 -> 0.245
A27: 23 | B27: 44285 | C27: 0.50138889 | D27: -7 | E27: 106.56 | F27: 128 | G27: 3.4 | M27: 7 | N27: =($N$16/(10-$M$21))*(M27-$M$21) -> 0.71978392 | O27: =N27-N26 -> 0.11996399 | P27: =N27-(O27/2) -> 0.65980193 | Q27: =N27+(O27/2) -> 0.77976591 | Z27: 2.7 | AA27: 4.5 | AB27: 0.40175614 | AC27: =(Z27-AA27)^2 -> 3.24 | AD27: =AC27/2 -> 1.62 | AE27: =AVERAGE(AB27:AB36) -> 0.46090662 | AF27: 0.5
A28: 24 | B28: 44320 | C28: 0.58545139 | D28: -6.992 | E28: 106.721 | F28: 72.2 | G28: 4.5 | M28: 8 | N28: =($N$16/(10-$M$21))*(M28-$M$21) -> 0.8397479 | O28: =N28-N27 -> 0.11996399 | P28: =N28-(O28/2) -> 0.77976591 | Q28: =N28+(O28/2) -> 0.8997299 | Z28: 2.7 | AA28: 2.8 | AB28: 0.40224371 | AC28: =(Z28-AA28)^2 -> 0.01 | AD28: =AC28/2 -> 0.005
A29: 25 | B29: 44301 | C29: 0.90038194 | D29: -7.52 | E29: 106.41 | F29: 67 | G29: 4.3 | M29: 9 | N29: =($N$16/(10-$M$21))*(M29-$M$21) -> 0.95971189 | O29: =N29-N28 -> 0.11996399 | P29: =N29-(O29/2) -> 0.8997299 | Q29: =N29+(O29/2) -> 1.0196939 | Z29: 3.1 | AA29: 3.5 | AB29: 0.40521599 | AC29: =(Z29-AA29)^2 -> 0.16 | AD29: =AC29/2 -> 0.08
A30: 26 | B30: 44301 | C30: 0.52009259 | D30: -7.35 | E30: 107.32 | F30: 129 | G30: 2.6 | M30: 10 | N30: =($N$16/(10-$M$21))*(M30-$M$21) -> 1.0796759 | O30: =N30-N29 -> 0.11996399 | P30: =N30-(O30/2) -> 1.0196939 | Q30: =N30+(O30/2) -> 1.1396579 | Z30: 3.5 | AA30: 4.5 | AB30: 0.41529267 | AC30: =(Z30-AA30)^2 -> 1 | AD30: =AC30/2 -> 0.5
A31: 27 | B31: 44306 | C31: 0.15539352 | D31: -7.1 | E31: 107.28 | F31: 185 | G31: 2.3 | Y31: offset 5 | Z31: 2.7 | AA31: 3.1 | AB31: 0.44777226 | AC31: =(Z31-AA31)^2 -> 0.16 | AD31: =AC31/2 -> 0.08 | AH31: Semivariogram exponential
A32: 28 | B32: 44307 | C32: 0.83523148 | D32: -7.63 | E32: 106.68 | F32: 25 | G32: 3.9 | Z32: 2.2 | AA32: 2.8 | AB32: 0.45099889 | AC32: =(Z32-AA32)^2 -> 0.36 | AD32: =AC32/2 -> 0.18
A33: 29 | B33: 44308 | C33: 0.10053241 | D33: -7.09 | E33: 106.78 | F33: 129 | G33: 3.2 | Z33: 3.2 | AA33: 2.7 | AB33: 0.45276926 | AC33: =(Z33-AA33)^2 -> 0.25 | AD33: =AC33/2 -> 0.125
A34: 30 | B34: 44310 | C34: 0.76396991 | D34: -7.31 | E34: 108.62 | F34: 10 | G34: 2.2 | Z34: 3.2 | AA34: 2.2 | AB34: 0.45276926 | AC34: =(Z34-AA34)^2 -> 1 | AD34: =AC34/2 -> 0.5
A35: 31 | B35: 44310 | C35: 0.93601852 | D35: -7.27 | E35: 107.72 | F35: 10 | G35: 2.9 | Y35: offset 6 | Z35: 3.2 | AA35: 2.8 | AB35: 0.58821765 | AC35: =(Z35-AA35)^2 -> 0.16 | AD35: =AC35/2 -> 0.08
A36: 32 | B36: 44313 | C36: 0.61944444 | D36: -6.8 | E36: 107.13 | F36: 10 | G36: 3.2 | Z36: 3.6 | AA36: 2.8 | AB36: 0.5920304 | AC36: =(Z36-AA36)^2 -> 0.64 | AD36: =AC36/2 -> 0.32
A37: 33 | B37: 44313 | C37: 0.24145833 | D37: -6.95 | E37: 106.99 | F37: 10 | G37: 3 | Z37: 3.2 | AA37: 4.5 | AB37: 0.64498682 | AC37: =(Z37-AA37)^2 -> 1.69 | AD37: =AC37/2 -> 0.845 | AE37: =AVERAGE(AB37:AB52) -> 0.72346104 | AF37: 0.7 | AH37: Semivariogram gaussian
A38: 34 | B38: 44315 | C38: 0.73792824 | D38: -7.69 | E38: 106.95 | F38: 26 | G38: 2.4 | Z38: 3.2 | AA38: 3.2 | AB38: 0.65513357 | AC38: =(Z38-AA38)^2 -> 0 | AD38: =AC38/2 -> 0
A39: 35 | B39: 44315 | C39: 0.012696759 | D39: -7 | E39: 107.68 | F39: 142 | G39: 3 | Z39: 3.2 | AA39: 3.6 | AB39: 0.65734314 | AC39: =(Z39-AA39)^2 -> 0.16 | AD39: =AC39/2 -> 0.08
A40: 36 | B40: 44315 | C40: 0.37664352 | D40: -6.9 | E40: 106.39 | F40: 15 | G40: 2.9 | Y40: offset 7 | Z40: 3.2 | AA40: 3.1 | AB40: 0.66370174 | AC40: =(Z40-AA40)^2 -> 0.01 | AD40: =AC40/2 -> 0.005
...

Sheet Kriging
AR1: Matriks kovarians data sigma(Z(si),Z(sj))) | AU1: h sesuai binning data | BD1: vektor kovarians data dengan prediksi | BH1: Bobot Kriging (lambda) | BJ1: OK | BK1: SK | BN1: Data | BO1: prediksi
A2: Data Kekuatan Gempa Bumi Jawa Barat Tahun 2021 | K2: 3.2 | L2: 2.7 | M2: 3.2 | N2: 3.2 | O2: 2.2 | P2: 3.6 | Q2: 3.1 | R2: 3.5 | S2: 4.5 | T2: 2.8 | AC2: Menentukan semivarian
A3: Lokasi | B3: Tanggal | C3: Jam | D3: Lintang (x) | E3: Bujur (y) | F3: Kedalaman (km) | G3: Magnitudo (R) | J3: Lokasi | K3: 1 | L3: 2 | M3: 3 | N3: 4 | O3: 5 | P3: 6 | Q3: 7 | R3: 8 | S3: 9 | T3: 10 | U3: 11 | W3: zi | X3: zj | Y3: jarak(h) | Z3: (zi-zj)^2 | AA3: semivarians | AC3: Offset | AD3: banyak lokasi | AE3: sigma(zi-zj)^2 | AF3: bin center | AG3: bin range | AI3: semivarians | AK3: spherical | AL3: exponential | AM3: gaussian | AN3: SE sphr | AO3: SE exp | AP3: SE gau | AR3: si,sj | AS3: 1 | AT3: 2 | AU3: 3 | AV3: 4 | AW3: 5 | AX3: 6 | AY3: 7 | AZ3: 8 | BA3: 9 | BB3: 10 | BD3: si,s0 | BE3: 11 | BH3: 1 | BI3: -0.3855 | BJ3: =BI3*G5 -> -1.2336 | BK3: =BI3*(G5-$N$15) -> 0 | BN3: s11 | BO3: OK | BP3: SK
I4: 3.2 | J4: 1 | K4: =SQRT(('Olah Semivariogram'!$D$5-'Olah Semivariogram'!D5)^2+('Olah Semivariogram'!$E$5-'Olah Semivariogram'!E5)^2) -> 0 | L4: =SQRT(('Olah Semivariogram'!$D$6-'Olah Semivariogram'!D5)^2+('Olah Semivariogram'!$E$6-'Olah Semivariogram'!E5)^2) -> 0.45276926 | M4: =SQRT(('Olah Semivariogram'!$D$7-'Olah Semivariogram'!D5)^2+('Olah Semivariogram'!$E$7-'Olah Semivariogram'!E5)^2) -> 0.72801099 | N4: =SQRT(('Olah Semivariogram'!$D$8-'Olah Semivariogram'!D5)^2+('Olah Semivariogram'!$E$8-'Olah Semivariogram'!E5)^2) -> 0.65513357 | O4: =SQRT(('Olah Semivariogram'!$D$9-'Olah Semivariogram'!D5)^2+('Olah Semivariogram'!$E$9-'Olah Semivariogram'!E5)^2) -> 0.45276926 | P4: =SQRT(('Olah Semivariogram'!$D$10-'Olah Semivariogram'!D5)^2+('Olah Semivariogram'!$E$10-'Olah Semivariogram'!E5)^2) -> 0.65734314 | Q4: =SQRT(('Olah Semivariogram'!$D$11-'Olah Semivariogram'!D5)^2+('Olah Semivariogram'!$E$11-'Olah Semivariogram'!E5)^2) -> 0.13601471 | R4: =SQRT(('Olah Semivariogram'!$D$12-'Olah Semivariogram'!D5)^2+('Olah Semivariogram'!$E$12-'Olah Semivariogram'!E5)^2) -> 0.33837849 | S4: =SQRT(('Olah Semivariogram'!$D$13-'Olah Semivariogram'!D5)^2+('Olah Semivariogram'!$E$13-'Olah Semivariogram'!E5)^2) -> 0.09963935 | T4: =SQRT(('Olah Semivariogram'!$D$14-'Olah Semivariogram'!D5)^2+('Olah Semivariogram'!$E$14-'Olah Semivariogram'!E5)^2) -> 0.08 | U4: =SQRT((D5-$D$15)^2+(E5-$E$15)^2) -> 0.18384776 | V4: offset 1 | W4: 3.2 | X4: 3.2 | Y4: 0 | Z4: =(W4-X4)^2 -> 0 | AA4: =Z4/20 -> 0 | AC4: 1 | AD4: =COUNT(W4:W13) -> 10 | AE4: =SUM(Z4:Z13) -> 0 | AF4: 0 | AG4: 0 | AH4: 0 | AI4: 0 | AK4: 0 | AL4: 0 | AM4: 0 | AN4: 0 | AO4: 0 | AP4: 0 | AR4: 1 | AS4: =IF(K4=0,0,IF(K4<=$N$22,$AK$19*(1.5*($K$22/$AK$20)-0.5*($K$22/$AK$20)^3),IF(K4<=$N$23,$AK$19*(1.5*($K$23/$AK$20)-0.5*($K$23/$AK$20)^3),IF(K4<=$N$24,$AK$19*(1.5*($K$24/$AK$20)-0.5*($K$24/$AK$20)^3),IF(K4<=$K$25,$AK$19*(1.5*($K$25/$AK$20)-0.5*($K$25/$AK$20)^3), $AK$19))))) -> 0 | AT4: =IF(L4=0,0,IF(L4<=$N$22,$AK$19*(1.5*($K$22/$AK$20)-0.5*($K$22/$AK$20)^3),IF(L4<=$N$23,$AK$19*(1.5*($K$23/$AK$20)-0.5*($K$23/$AK$20)^3),IF(L4<=$N$24,$AK$19*(1.5*($K$24/$AK$20)-0.5*($K$24/$AK$20)^3),IF(L4<=$K$25,$AK$19*(1.5*($K$25/$AK$20)-0.5*($K$25/$AK$20)^3), $AK$19))))) -> 0.419125 | AU4: =IF(M4=0,0,IF(M4<=$N$22,$AK$19*(1.5*($K$22/$AK$20)-0.5*($K$22/$AK$20)^3),IF(M4<=$N$23,$AK$19*(1.5*($K$23/$AK$20)-0.5*($K$23/$AK$20)^3),IF(M4<=$N$24,$AK$19*(1.5*($K$24/$AK$20)-0.5*($K$24/$AK$20)^3),IF(M4<=$K$25,$AK$19*(1.5*($K$25/$AK$20)-0.5*($K$25/$AK$20)^3), $AK$19))))) -> 0.419125 | AV4: =IF(N4=0,0,IF(N4<=$N$22,$AK$19*(1.5*($K$22/$AK$20)-0.5*($K$22/$AK$20)^3),IF(N4<=$N$23,$AK$19*(1.5*($K$23/$AK$20)-0.5*($K$23/$AK$20)^3),IF(N4<=$N$24,$AK$19*(1.5*($K$24/$AK$20)-0.5*($K$24/$AK$20)^3),IF(N4<=$K$25,$AK$19*(1.5*($K$25/$AK$20)-0.5*($K$25/$AK$20)^3), $AK$19))))) -> 0.419125 | AW4: =IF(O4=0,0,IF(O4<=$N$22,$AK$19*(1.5*($K$22/$AK$20)-0.5*($K$22/$AK$20)^3),IF(O4<=$N$23,$AK$19*(1.5*($K$23/$AK$20)-0.5*($K$23/$AK$20)^3),IF(O4<=$N$24,$AK$19*(1.5*($K$24/$AK$20)-0.5*($K$24/$AK$20)^3),IF(O4<=$K$25,$AK$19*(1.5*($K$25/$AK$20)-0.5*($K$25/$AK$20)^3), $AK$19))))) -> 0.419125 | AX4: =IF(P4=0,0,IF(P4<=$N$22,$AK$19*(1.5*($K$22/$AK$20)-0.5*($K$22/$AK$20)^3),IF(P4<=$N$23,$AK$19*(1.5*($K$23/$AK$20)-0.5*($K$23/$AK$20)^3),IF(P4<=$N$24,$AK$19*(1.5*($K$24/$AK$20)-0.5*($K$24/$AK$20)^3),IF(P4<=$K$25,$AK$19*(1.5*($K$25/$AK$20)-0.5*($K$25/$AK$20)^3), $AK$19))))) -> 0.419125 | AY4: =IF(Q4=0,0,IF(Q4<=$N$22,$AK$19*(1.5*($K$22/$AK$20)-0.5*($K$22/$AK$20)^3),IF(Q4<=$N$23,$AK$19*(1.5*($K$23/$AK$20)-0.5*($K$23/$AK$20)^3),IF(Q4<=$N$24,$AK$19*(1.5*($K$24/$AK$20)-0.5*($K$24/$AK$20)^3),IF(Q4<=$K$25,$AK$19*(1.5*($K$25/$AK$20)-0.5*($K$25/$AK$20)^3), $AK$19))))) -> 0.15389746 | AZ4: =IF(R4=0,0,IF(R4<=$N$22,$AK$19*(1.5*($K$22/$AK$20)-0.5*($K$22/$AK$20)^3),IF(R4<=$N$23,$AK$19*(1.5*($K$23/$AK$20)-0.5*($K$23/$AK$20)^3),IF(R4<=$N$24,$AK$19*(1.5*($K$24/$AK$20)-0.5*($K$24/$AK$20)^3),IF(R4<=$K$25,$AK$19*(1.5*($K$25/$AK$20)-0.5*($K$25/$AK$20)^3), $AK$19))))) -> 0.38310645 | ... BB4: =IF(T4=0,0,IF(T4<=$N$22,$AK$19*(1.5*($K$22/$AK$20)-0.5*($K$22/$AK$20)^3),IF(T4<=$N$23,$AK$19*(1.5*($K$23/$AK$20)-0.5*($K$23/$AK$20)^3),IF(T4<=$N$24,$AK$19*(1.5*($K$24/$AK$20)-0.5*($K$24/$AK$20)^3),IF(T4<=$K$25,$AK$19*(1.5*($K$25/$AK$20)-0.5*($K$25/$AK$20)^3), $AK$19))))) -> 0.15389746 | BD4: 1 | BE4: =IF(U4=0,0,IF(U4<=$N$22,$AK$19*(1.5*($K$22/$AK$20)-0.5*($K$22/$AK$20)^3),IF(U4<=$N$23,$AK$19*(1.5*($K$23/$AK$20)-0.5*($K$23/$AK$20)^3),IF(U4<=$N$24,$AK$19*(1.5*($K$24/$AK$20)-0.5*($K$24/$AK$20)^3),IF(U4<=$K$25,$AK$19*(1.5*($K$25/$AK$20)-0.5*($K$25/$AK$20)^3), $AK$19))))) -> 0.28814844 | BH4: 2 | BI4: -0.0122 | BJ4: =BI4*G6 -> -0.03294 | BK4: =BI4*(G6-$N$15) -> 0.0061 | BN4: =$G$15 -> 2.9 | BO4: =BJ13 -> 3.89862 | BP4: =BK13 -> 3.69926
A5: 1 | B5: 44201 | C5: 0.98804398 | D5: -7.47 | E5: 106.71 | F5: 36 | G5: 3.2 | I5: 2.7 | J5: 2 | K5: =SQRT(('Olah Semivariogram'!$D$5-'Olah Semivariogram'!D6)^2+('Olah Semivariogram'!$E$5-'Olah Semivariogram'!E6)^2) -> 0.45276926 | L5: =SQRT(('Olah Semivariogram'!$D$6-'Olah Semivariogram'!D6)^2+('Olah Semivariogram'!$E$6-'Olah Semivariogram'!E6)^2) -> 0 | M5: =SQRT(('Olah Semivariogram'!$D$7-'Olah Semivariogram'!D6)^2+('Olah Semivariogram'!$E$7-'Olah Semivariogram'!E6)^2) -> 0.35355339 | N5: =SQRT(('Olah Semivariogram'!$D$8-'Olah Semivariogram'!D6)^2+('Olah Semivariogram'!$E$8-'Olah Semivariogram'!E6)^2) -> 0.71512237 | O5: =SQRT(('Olah Semivariogram'!$D$9-'Olah Semivariogram'!D6)^2+('Olah Semivariogram'!$E$9-'Olah Semivariogram'!E6)^2) -> 0.28635642 | P5: =SQRT(('Olah Semivariogram'!$D$10-'Olah Semivariogram'!D6)^2+('Olah Semivariogram'!$E$10-'Olah Semivariogram'!E6)^2) -> 0.73054774 | Q5: =SQRT(('Olah Semivariogram'!$D$11-'Olah Semivariogram'!D6)^2+('Olah Semivariogram'!$E$11-'Olah Semivariogram'!E6)^2) -> 0.44777226 | R5: =SQRT(('Olah Semivariogram'!$D$12-'Olah Semivariogram'!D6)^2+('Olah Semivariogram'!$E$12-'Olah Semivariogram'!E6)^2) -> 0.78873316 | S5: =SQRT(('Olah Semivariogram'!$D$13-'Olah Semivariogram'!D6)^2+('Olah Semivariogram'!$E$13-'Olah Semivariogram'!E6)^2) -> 0.40175614 | T5: =SQRT(('Olah Semivariogram'!$D$14-'Olah Semivariogram'!D6)^2+('Olah Semivariogram'!$E$14-'Olah Semivariogram'!E6)^2) -> 0.40224371 | U5: =SQRT((D6-$D$15)^2+(E6-$E$15)^2) -> 0.48332184 | W5: 2.7 | X5: 2.7 | Y5: 0 | Z5: =(W5-X5)^2 -> 0 | AA5: =Z5/20 -> 0 | AC5: 2 | AD5: =COUNT(W14:W19) -> 6 | AE5: =SUM(Z14:Z19) -> 6.87 | AF5: =MEDIAN(AG5,AH5) -> 0.11996399 | AG5: 0.059981993 | AH5: 0.17994598 | AI5: =AE5/(2*AD5) -> 0.5725 | AK5: =$AI$19*(1.5*(AF5/$AI$20)-0.5*(AF5/$AI$20)^3) -> 0.17473724 | AL5: =$AI$19*(1-EXP(-(AF5/$AI$20))) -> 0.10416208 | AM5: =$AI$19*(1-EXP(-((AF5)^2/($AI$20)^2))) -> 0.032855021 | AN5: =(AK5-AI5)^2 -> 0.15821521 | AO5: =(AL5-AI5)^2 -> 0.21934041 | AP5: =(AM5-AI5)^2 -> 0.2912167 | AR5: 2 | AS5: =IF(K5=0,0,IF(K5<=$N$22,$AK$19*(1.5*($K$22/$AK$20)-0.5*($K$22/$AK$20)^3),IF(K5<=$N$23,$AK$19*(1.5*($K$23/$AK$20)-0.5*($K$23/$AK$20)^3),IF(K5<=$N$24,$AK$19*(1.5*($K$24/$AK$20)-0.5*($K$24/$AK$20)^3),IF(K5<=$K$25,$AK$19*(1.5*($K$25/$AK$20)-0.5*($K$25/$AK$20)^3), $AK$19))))) -> 0.419125 | AT5: =IF(L5=0,0,IF(L5<=$N$22,$AK$19*(1.5*($K$22/$AK$20)-0.5*($K$22/$AK$20)^3),IF(L5<=$N$23,$AK$19*(1.5*($K$23/$AK$20)-0.5*($K$23/$AK$20)^3),IF(L5<=$N$24,$AK$19*(1.5*($K$24/$AK$20)-0.5*($K$24/$AK$20)^3),IF(L5<=$K$25,$AK$19*(1.5*($K$25/$AK$20)-0.5*($K$25/$AK$20)^3), $AK$19))))) -> 0 | AU5: =IF(M5=0,0,IF(M5<=$N$22,$AK$19*(1.5*($K$22/$AK$20)-0.5*($K$22/$AK$20)^3),IF(M5<=$N$23,$AK$19*(1.5*($K$23/$AK$20)-0.5*($K$23/$AK$20)^3),IF(M5<=$N$24,$AK$19*(1.5*($K$24/$AK$20)-0.5*($K$24/$AK$20)^3),IF(M5<=$K$25,$AK$19*(1.5*($K$25/$AK$20)-0.5*($K$25/$AK$20)^3), $AK$19))))) -> 0.38310645 | AV5: =IF(N5=0,0,IF(N5<=$N$22,$AK$19*(1.5*($K$22/$AK$20)-0.5*($K$22/$AK$20)^3),IF(N5<=$N$23,$AK$19*(1.5*($K$23/$AK$20)-0.5*($K$23/$AK$20)^3),IF(N5<=$N$24,$AK$19*(1.5*($K$24/$AK$20)-0.5*($K$24/$AK$20)^3),IF(N5<=$K$25,$AK$19*(1.5*($K$25/$AK$20)-0.5*($K$25/$AK$20)^3), $AK$19))))) -> 0.419125 | AW5: =IF(O5=0,0,IF(O5<=$N$22,$AK$19*(1.5*($K$22/$AK$20)-0.5*($K$22/$AK$20)^3),IF(O5<=$N$23,$AK$19*(1.5*($K$23/$AK$20)-0.5*($K$23/$AK$20)^3),IF(O5<=$N$24,$AK$19*(1.5*($K$24/$AK$20)-0.5*($K$24/$AK$20)^3),IF(O5<=$K$25,$AK$19*(1.5*($K$25/$AK$20)-0.5*($K$25/$AK$20)^3), $AK$19))))) -> 0.28814844 | AX5: =IF(P5=0,0,IF(P5<=$N$22,$AK$19*(1.5*($K$22/$AK$20)-0.5*($K$22/$AK$20)^3),IF(P5<=$N$23,$AK$19*(1.5*($K$23/$AK$20)-0.5*($K$23/$AK$20)^3),IF(P5<=$N$24,$AK$19*(1.5*($K$24/$AK$20)-0.5*($K$24/$AK$20)^3),IF(P5<=$K$25,$AK$19*(1.5*($K$25/$AK$20)-0.5*($K$25/$AK$20)^3), $AK$19))))) -> 0.419125 | AY5: =IF(Q5=0,0,IF(Q5<=$N$22,$AK$19*(1.5*($K$22/$AK$20)-0.5*($K$22/$AK$20)^3),IF(Q5<=$N$23,$AK$19*(1.5*($K$23/$AK$20)-0.5*($K$23/$AK$20)^3),IF(Q5<=$N$24,$AK$19*(1.5*($K$24/$AK$20)-0.5*($K$24/$AK$20)^3),IF(Q5<=$K$25,$AK$19*(1.5*($K$25/$AK$20)-0.5*($K$25/$AK$20)^3), $AK$19))))) -> 0.419125 | AZ5: =IF(R5=0,0,IF(R5<=$N$22,$AK$19*(1.5*($K$22/$AK$20)-0.5*($K$22/$AK$20)^3),IF(R5<=$N$23,$AK$19*(1.5*($K$23/$AK$20)-0.5*($K$23/$AK$20)^3),IF(R5<=$N$24,$AK$19*(1.5*($K$24/$AK$20)-0.5*($K$24/$AK$20)^3),IF(R5<=$K$25,$AK$19*(1.5*($K$25/$AK$20)-0.5*($K$25/$AK$20)^3), $AK$19))))) -> 0.419125 | ... BB5: =IF(T5=0,0,IF(T5<=$N$22,$AK$19*(1.5*($K$22/$AK$20)-0.5*($K$22/$AK$20)^3),IF(T5<=$N$23,$AK$19*(1.5*($K$23/$AK$20)-0.5*($K$23/$AK$20)^3),IF(T5<=$N$24,$AK$19*(1.5*($K$24/$AK$20)-0.5*($K$24/$AK$20)^3),IF(T5<=$K$25,$AK$19*(1.5*($K$25/$AK$20)-0.5*($K$25/$AK$20)^3), $AK$19))))) -> 0.38310645 | BD5: 2 | BE5: =IF(U5=0,0,IF(U5<=$N$22,$AK$19*(1.5*($K$22/$AK$20)-0.5*($K$22/$AK$20)^3),IF(U5<=$N$23,$AK$19*(1.5*($K$23/$AK$20)-0.5*($K$23/$AK$20)^3),IF(U5<=$N$24,$AK$19*(1.5*($K$24/$AK$20)-0.5*($K$24/$AK$20)^3),IF(U5<=$K$25,$AK$19*(1.5*($K$25/$AK$20)-0.5*($K$25/$AK$20)^3), $AK$19))))) -> 0.419125 | BH5: 3 | BI5: 0.0585 | BJ5: =BI5*G7 -> 0.1872 | BK5: =BI5*(G7-$N$15) -> 0 | BO5: =BJ34 -> 3.19206 | BP5: =BK34 -> 3.03782
A6: 2 | B6: 44203 | C6: 0.30513889 | D6: -7.14 | E6: 107.02 | F6: 81 | G6: 2.7 | I6: 3.2 | J6: 3 | K6: =SQRT(('Olah Semivariogram'!$D$5-'Olah Semivariogram'!D7)^2+('Olah Semivariogram'!$E$5-'Olah Semivariogram'!E7)^2) -> 0.72801099 | L6: =SQRT(('Olah Semivariogram'!$D$6-'Olah Semivariogram'!D7)^2+('Olah Semivariogram'!$E$6-'Olah Semivariogram'!E7)^2) -> 0.35355339 | M6: =SQRT(('Olah Semivariogram'!$D$7-'Olah Semivariogram'!D7)^2+('Olah Semivariogram'!$E$7-'Olah Semivariogram'!E7)^2) -> 0 | N6: =SQRT(('Olah Semivariogram'!$D$8-'Olah Semivariogram'!D7)^2+('Olah Semivariogram'!$E$8-'Olah Semivariogram'!E7)^2) -> 1.0632027 | O6: =SQRT(('Olah Semivariogram'!$D$9-'Olah Semivariogram'!D7)^2+('Olah Semivariogram'!$E$9-'Olah Semivariogram'!E7)^2) -> 0.31144823 | P6: =SQRT(('Olah Semivariogram'!$D$10-'Olah Semivariogram'!D7)^2+('Olah Semivariogram'!$E$10-'Olah Semivariogram'!E7)^2) -> 1.0796759 | Q6: =SQRT(('Olah Semivariogram'!$D$11-'Olah Semivariogram'!D7)^2+('Olah Semivariogram'!$E$11-'Olah Semivariogram'!E7)^2) -> 0.66370174 | R6: =SQRT(('Olah Semivariogram'!$D$12-'Olah Semivariogram'!D7)^2+('Olah Semivariogram'!$E$12-'Olah Semivariogram'!E7)^2) -> 1.0602358 | S6: =SQRT(('Olah Semivariogram'!$D$13-'Olah Semivariogram'!D7)^2+('Olah Semivariogram'!$E$13-'Olah Semivariogram'!E7)^2) -> 0.64498682 | T6: =SQRT(('Olah Semivariogram'!$D$14-'Olah Semivariogram'!D7)^2+('Olah Semivariogram'!$E$14-'Olah Semivariogram'!E7)^2) -> 0.70342022 | U6: =SQRT((D7-$D$15)^2+(E7-$E$15)^2) -> 0.67424031 | W6: 3.2 | X6: 3.2 | Y6: 0 | Z6: =(W6-X6)^2 -> 0 | AA6: =Z6/20 -> 0 | AC6: 3 | AD6: =COUNTA(W20:W21) -> 2 | AE6: =SUM(Z20:Z21) -> 0.34 | AF6: =MEDIAN(AG6,AH6) -> 0.23992797 | AG6: 0.17994598 | AH6: 0.29990997 | AI6: =AE6/(2*AD6) -> 0.085 | AK6: =$AI$19*(1.5*(AF6/$AI$20)-0.5*(AF6/$AI$20)^3) -> 0.32014796 | AL6: =$AI$19*(1-EXP(-(AF6/$AI$20))) -> 0.18243752 | AM6: =$AI$19*(1-EXP(-((AF6)^2/($AI$20)^2))) -> 0.11675888 | AN6: =(AK6-AI6)^2 -> 0.055294563 | AO6: =(AL6-AI6)^2 -> 0.0094940697 | AP6: =(AM6-AI6)^2 -> 0.0010086266 | AR6: 3 | AS6: =IF(K6=0,0,IF(K6<=$N$22,$AK$19*(1.5*($K$22/$AK$20)-0.5*($K$22/$AK$20)^3),IF(K6<=$N$23,$AK$19*(1.5*($K$23/$AK$20)-0.5*($K$23/$AK$20)^3),IF(K6<=$N$24,$AK$19*(1.5*($K$24/$AK$20)-0.5*($K$24/$AK$20)^3),IF(K6<=$K$25,$AK$19*(1.5*($K$25/$AK$20)-0.5*($K$25/$AK$20)^3), $AK$19))))) -> 0.419125 | AT6: =IF(L6=0,0,IF(L6<=$N$22,$AK$19*(1.5*($K$22/$AK$20)-0.5*($K$22/$AK$20)^3),IF(L6<=$N$23,$AK$19*(1.5*($K$23/$AK$20)-0.5*($K$23/$AK$20)^3),IF(L6<=$N$24,$AK$19*(1.5*($K$24/$AK$20)-0.5*($K$24/$AK$20)^3),IF(L6<=$K$25,$AK$19*(1.5*($K$25/$AK$20)-0.5*($K$25/$AK$20)^3), $AK$19))))) -> 0.38310645 | AU6: =IF(M6=0,0,IF(M6<=$N$22,$AK$19*(1.5*($K$22/$AK$20)-0.5*($K$22/$AK$20)^3),IF(M6<=$N$23,$AK$19*(1.5*($K$23/$AK$20)-0.5*($K$23/$AK$20)^3),IF(M6<=$N$24,$AK$19*(1.5*($K$24/$AK$20)-0.5*($K$24/$AK$20)^3),IF(M6<=$K$25,$AK$19*(1.5*($K$25/$AK$20)-0.5*($K$25/$AK$20)^3), $AK$19))))) -> 0 | AV6: =IF(N6=0,0,IF(N6<=$N$22,$AK$19*(1.5*($K$22/$AK$20)-0.5*($K$22/$AK$20)^3),IF(N6<=$N$23,$AK$19*(1.5*($K$23/$AK$20)-0.5*($K$23/$AK$20)^3),IF(N6<=$N$24,$AK$19*(1.5*($K$24/$AK$20)-0.5*($K$24/$AK$20)^3),IF(N6<=$K$25,$AK$19*(1.5*($K$25/$AK$20)-0.5*($K$25/$AK$20)^3), $AK$19))))) -> 0.419125 | AW6: =IF(O6=0,0,IF(O6<=$N$22,$AK$19*(1.5*($K$22/$AK$20)-0.5*($K$22/$AK$20)^3),IF(O6<=$N$23,$AK$19*(1.5*($K$23/$AK$20)-0.5*($K$23/$AK$20)^3),IF(O6<=$N$24,$AK$19*(1.5*($K$24/$AK$20)-0.5*($K$24/$AK$20)^3),IF(O6<=$K$25,$AK$19*(1.5*($K$25/$AK$20)-0.5*($K$25/$AK$20)^3), $AK$19))))) -> 0.38310645 | AX6: =IF(P6=0,0,IF(P6<=$N$22,$AK$19*(1.5*($K$22/$AK$20)-0.5*($K$22/$AK$20)^3),IF(P6<=$N$23,$AK$19*(1.5*($K$23/$AK$20)-0.5*($K$23/$AK$20)^3),IF(P6<=$N$24,$AK$19*(1.5*($K$24/$AK$20)-0.5*($K$24/$AK$20)^3),IF(P6<=$K$25,$AK$19*(1.5*($K$25/$AK$20)-0.5*($K$25/$AK$20)^3), $AK$19))))) -> 0.419125 | AY6: =IF(Q6=0,0,IF(Q6<=$N$22,$AK$19*(1.5*($K$22/$AK$20)-0.5*($K$22/$AK$20)^3),IF(Q6<=$N$23,$AK$19*(1.5*($K$23/$AK$20)-0.5*($K$23/$AK$20)^3),IF(Q6<=$N$24,$AK$19*(1.5*($K$24/$AK$20)-0.5*($K$24/$AK$20)^3),IF(Q6<=$K$25,$AK$19*(1.5*($K$25/$AK$20)-0.5*($K$25/$AK$20)^3), $AK$19))))) -> 0.419125 | AZ6: =IF(R6=0,0,IF(R6<=$N$22,$AK$19*(1.5*($K$22/$AK$20)-0.5*($K$22/$AK$20)^3),IF(R6<=$N$23,$AK$19*(1.5*($K$23/$AK$20)-0.5*($K$23/$AK$20)^3),IF(R6<=$N$24,$AK$19*(1.5*($K$24/$AK$20)-0.5*($K$24/$AK$20)^3),IF(R6<=$K$25,$AK$19*(1.5*($K$25/$AK$20)-0.5*($K$25/$AK$20)^3), $AK$19))))) -> 0.419125 | ... BB6: =IF(T6=0,0,IF(T6<=$N$22,$AK$19*(1.5*($K$22/$AK$20)-0.5*($K$22/$AK$20)^3),IF(T6<=$N$23,$AK$19*(1.5*($K$23/$AK$20)-0.5*($K$23/$AK$20)^3),IF(T6<=$N$24,$AK$19*(1.5*($K$24/$AK$20)-0.5*($K$24/$AK$20)^3),IF(T6<=$K$25,$AK$19*(1.5*($K$25/$AK$20)-0.5*($K$25/$AK$20)^3), $AK$19))))) -> 0.419125 | BD6: 3 | BE6: =IF(U6=0,0,IF(U6<=$N$22,$AK$19*(1.5*($K$22/$AK$20)-0.5*($K$22/$AK$20)^3),IF(U6<=$N$23,$AK$19*(1.5*($K$23/$AK$20)-0.5*($K$23/$AK$20)^3),IF(U6<=$N$24,$AK$19*(1.5*($K$24/$AK$20)-0.5*($K$24/$AK$20)^3),IF(U6<=$K$25,$AK$19*(1.5*($K$25/$AK$20)-0.5*($K$25/$AK$20)^3), $AK$19))))) -> 0.419125 | BH6: 4 | BI6: 0.0381 | BJ6: =BI6*G8 -> 0.12192 | BK6: =BI6*(G8-$N$15) -> 0 | BO6: =BJ51 -> 2.50176 | BP6: =BK51 -> 2.8272
A7: 3 | B7: 44207 | C7: 0.52436343 | D7: -6.79 | E7: 106.97 | F7: 10 | G7: 3.2 | I7: 3.2 | J7: 4 | K7: =SQRT(('Olah Semivariogram'!$D$5-'Olah Semivariogram'!D8)^2+('Olah Semivariogram'!$E$5-'Olah Semivariogram'!E8)^2) -> 0.65513357 | L7: =SQRT(('Olah Semivariogram'!$D$6-'Olah Semivariogram'!D8)^2+('Olah Semivariogram'!$E$6-'Olah Semivariogram'!E8)^2) -> 0.71512237 | M7: =SQRT(('Olah Semivariogram'!$D$7-'Olah Semivariogram'!D8)^2+('Olah Semivariogram'!$E$7-'Olah Semivariogram'!E8)^2) -> 1.0632027 | N7: =SQRT(('Olah Semivariogram'!$D$8-'Olah Semivariogram'!D8)^2+('Olah Semivariogram'!$E$8-'Olah Semivariogram'!E8)^2) -> 0 | O7: =SQRT(('Olah Semivariogram'!$D$9-'Olah Semivariogram'!D8)^2+('Olah Semivariogram'!$E$9-'Olah Semivariogram'!E8)^2) -> 0.94031909 | P7: =SQRT(('Olah Semivariogram'!$D$10-'Olah Semivariogram'!D8)^2+('Olah Semivariogram'!$E$10-'Olah Semivariogram'!E8)^2) -> 0.02236068 | Q7: =SQRT(('Olah Semivariogram'!$D$11-'Olah Semivariogram'!D8)^2+('Olah Semivariogram'!$E$11-'Olah Semivariogram'!E8)^2) -> 0.7823682 | R7: =SQRT(('Olah Semivariogram'!$D$12-'Olah Semivariogram'!D8)^2+('Olah Semivariogram'!$E$12-'Olah Semivariogram'!E8)^2) -> 0.75239617 | S7: =SQRT(('Olah Semivariogram'!$D$13-'Olah Semivariogram'!D8)^2+('Olah Semivariogram'!$E$13-'Olah Semivariogram'!E8)^2) -> 0.72520894 | T7: =SQRT(('Olah Semivariogram'!$D$14-'Olah Semivariogram'!D8)^2+('Olah Semivariogram'!$E$14-'Olah Semivariogram'!E8)^2) -> 0.58821765 | U7: =SQRT((D8-$D$15)^2+(E8-$E$15)^2) -> 0.83486526 | W7: 3.2 | X7: 3.2 | Y7: 0 | Z7: =(W7-X7)^2 -> 0 | AA7: =Z7/20 -> 0 | AC7: 4 | AD7: =COUNT(W22:W31) -> 10 | AE7: =SUM(Z22:Z31) -> 12.34 | AF7: =MEDIAN(AG7,AH7) -> 0.35989196 | AG7: 0.29990997 | AH7: 0.41987395 | AI7: =AE7/(2*AD7) -> 0.617 | AK7: =$AI$19*(1.5*(AF7/$AI$20)-0.5*(AF7/$AI$20)^3) -> 0.40690561 | AL7: =$AI$19*(1-EXP(-(AF7/$AI$20))) -> 0.24125973 | AM7: =$AI$19*(1-EXP(-((AF7)^2/($AI$20)^2))) -> 0.21809074 | AN7: =(AK7-AI7)^2 -> 0.044139652 | AO7: =(AL7-AI7)^2 -> 0.14118075 | AP7: =(AM7-AI7)^2 -> 0.1591286 | AR7: 4 | AS7: =IF(K7=0,0,IF(K7<=$N$22,$AK$19*(1.5*($K$22/$AK$20)-0.5*($K$22/$AK$20)^3),IF(K7<=$N$23,$AK$19*(1.5*($K$23/$AK$20)-0.5*($K$23/$AK$20)^3),IF(K7<=$N$24,$AK$19*(1.5*($K$24/$AK$20)-0.5*($K$24/$AK$20)^3),IF(K7<=$K$25,$AK$19*(1.5*($K$25/$AK$20)-0.5*($K$25/$AK$20)^3), $AK$19))))) -> 0.419125 | AT7: =IF(L7=0,0,IF(L7<=$N$22,$AK$19*(1.5*($K$22/$AK$20)-0.5*($K$22/$AK$20)^3),IF(L7<=$N$23,$AK$19*(1.5*($K$23/$AK$20)-0.5*($K$23/$AK$20)^3),IF(L7<=$N$24,$AK$19*(1.5*($K$24/$AK$20)-0.5*($K$24/$AK$20)^3),IF(L7<=$K$25,$AK$19*(1.5*($K$25/$AK$20)-0.5*($K$25/$AK$20)^3), $AK$19))))) -> 0.419125 | AU7: =IF(M7=0,0,IF(M7<=$N$22,$AK$19*(1.5*($K$22/$AK$20)-0.5*($K$22/$AK$20)^3),IF(M7<=$N$23,$AK$19*(1.5*($K$23/$AK$20)-0.5*($K$23/$AK$20)^3),IF(M7<=$N$24,$AK$19*(1.5*($K$24/$AK$20)-0.5*($K$24/$AK$20)^3),IF(M7<=$K$25,$AK$19*(1.5*($K$25/$AK$20)-0.5*($K$25/$AK$20)^3), $AK$19))))) -> 0.419125 | AV7: =IF(N7=0,0,IF(N7<=$N$22,$AK$19*(1.5*($K$22/$AK$20)-0.5*($K$22/$AK$20)^3),IF(N7<=$N$23,$AK$19*(1.5*($K$23/$AK$20)-0.5*($K$23/$AK$20)^3),IF(N7<=$N$24,$AK$19*(1.5*($K$24/$AK$20)-0.5*($K$24/$AK$20)^3),IF(N7<=$K$25,$AK$19*(1.5*($K$25/$AK$20)-0.5*($K$25/$AK$20)^3), $AK$19))))) -> 0 | AW7: =IF(O7=0,0,IF(O7<=$N$22,$AK$19*(1.5*($K$22/$AK$20)-0.5*($K$22/$AK$20)^3),IF(O7<=$N$23,$AK$19*(1.5*($K$23/$AK$20)-0.5*($K$23/$AK$20)^3),IF(O7<=$N$24,$AK$19*(1.5*($K$24/$AK$20)-0.5*($K$24/$AK$20)^3),IF(O7<=$K$25,$AK$19*(1.5*($K$25/$AK$20)-0.5*($K$25/$AK$20)^3), $AK$19))))) -> 0.419125 | AX7: =IF(P7=0,0,IF(P7<=$N$22,$AK$19*(1.5*($K$22/$AK$20)-0.5*($K$22/$AK$20)^3),IF(P7<=$N$23,$AK$19*(1.5*($K$23/$AK$20)-0.5*($K$23/$AK$20)^3),IF(P7<=$N$24,$AK$19*(1.5*($K$24/$AK$20)-0.5*($K$24/$AK$20)^3),IF(P7<=$K$25,$AK$19*(1.5*($K$25/$AK$20)-0.5*($K$25/$AK$20)^3), $AK$19))))) -> 0.15389746 | AY7: =IF(Q7=0,0,IF(Q7<=$N$22,$AK$19*(1.5*($K$22/$AK$20)-0.5*($K$22/$AK$20)^3),IF(Q7<=$N$23,$AK$19*(1.5*($K$23/$AK$20)-0.5*($K$23/$AK$20)^3),IF(Q7<=$N$24,$AK$19*(1.5*($K$24/$AK$20)-0.5*($K$24/$AK$20)^3),IF(Q7<=$K$25,$AK$19*(1.5*($K$25/$AK$20)-0.5*($K$25/$AK$20)^3), $AK$19))))) -> 0.419125 | AZ7: =IF(R7=0,0,IF(R7<=$N$22,$AK$19*(1.5*($K$22/$AK$20)-0.5*($K$22/$AK$20)^3),IF(R7<=$N$23,$AK$19*(1.5*($K$23/$AK$20)-0.5*($K$23/$AK$20)^3),IF(R7<=$N$24,$AK$19*(1.5*($K$24/$AK$20)-0.5*($K$24/$AK$20)^3),IF(R7<=$K$25,$AK$19*(1.5*($K$25/$AK$20)-0.5*($K$25/$AK$20)^3), $AK$19))))) -> 0.419125 | ... BB7: =IF(T7=0,0,IF(T7<=$N$22,$AK$19*(1.5*($K$22/$AK$20)-0.5*($K$22/$AK$20)^3),IF(T7<=$N$23,$AK$19*(1.5*($K$23/$AK$20)-0.5*($K$23/$AK$20)^3),IF(T7<=$N$24,$AK$19*(1.5*($K$24/$AK$20)-0.5*($K$24/$AK$20)^3),IF(T7<=$K$25,$AK$19*(1.5*($K$25/$AK$20)-0.5*($K$25/$AK$20)^3), $AK$19))))) -> 0.419125 | BD7: 4 | BE7: =IF(U7=0,0,IF(U7<=$N$22,$AK$19*(1.5*($K$22/$AK$20)-0.5*($K$22/$AK$20)^3),IF(U7<=$N$23,$AK$19*(1.5*($K$23/$AK$20)-0.5*($K$23/$AK$20)^3),IF(U7<=$N$24,$AK$19*(1.5*($K$24/$AK$20)-0.5*($K$24/$AK$20)^3),IF(U7<=$K$25,$AK$19*(1.5*($K$25/$AK$20)-0.5*($K$25/$AK$20)^3), $AK$19))))) -> 0.419125 | BH7: 5 | BI7: 0.0556 | BJ7: =BI7*G9 -> 0.12232 | BK7: =BI7*(G9-$N$15) -> -0.0556
A8: 4 | B8: 44215 | C8: 0.6603588 | D8: -7.81 | E8: 107.27 | F8: 30 | G8: 3.2 | I8: 2.2 | J8: 5 | K8: =SQRT(('Olah Semivariogram'!$D$5-'Olah Semivariogram'!D9)^2+('Olah Semivariogram'!$E$5-'Olah Semivariogram'!E9)^2) -> 0.45276926 | L8: =SQRT(('Olah Semivariogram'!$D$6-'Olah Semivariogram'!D9)^2+('Olah Semivariogram'!$E$6-'Olah Semivariogram'!E9)^2) -> 0.28635642 | M8: =SQRT(('Olah Semivariogram'!$D$7-'Olah Semivariogram'!D9)^2+('Olah Semivariogram'!$E$7-'Olah Semivariogram'!E9)^2) -> 0.31144823 | N8: =SQRT(('Olah Semivariogram'!$D$8-'Olah Semivariogram'!D9)^2+('Olah Semivariogram'!$E$8-'Olah Semivariogram'!E9)^2) -> 0.94031909 | O8: =SQRT(('Olah Semivariogram'!$D$9-'Olah Semivariogram'!D9)^2+('Olah Semivariogram'!$E$9-'Olah Semivariogram'!E9)^2) -> 0 | P8: =SQRT(('Olah Semivariogram'!$D$10-'Olah Semivariogram'!D9)^2+('Olah Semivariogram'!$E$10-'Olah Semivariogram'!E9)^2) -> 0.95189285 | Q8: =SQRT(('Olah Semivariogram'!$D$11-'Olah Semivariogram'!D9)^2+('Olah Semivariogram'!$E$11-'Olah Semivariogram'!E9)^2) -> 0.36400549 | R8: =SQRT(('Olah Semivariogram'!$D$12-'Olah Semivariogram'!D9)^2+('Olah Semivariogram'!$E$12-'Olah Semivariogram'!E9)^2) -> 0.76843998 | S8: =SQRT(('Olah Semivariogram'!$D$13-'Olah Semivariogram'!D9)^2+('Olah Semivariogram'!$E$13-'Olah Semivariogram'!E9)^2) -> 0.35850802 | T8: =SQRT(('Olah Semivariogram'!$D$14-'Olah Semivariogram'!D9)^2+('Olah Semivariogram'!$E$14-'Olah Semivariogram'!E9)^2) -> 0.45099889 | U8: =SQRT((D9-$D$15)^2+(E9-$E$15)^2) -> 0.3671512 | W8: 2.2 | X8: 2.2 | Y8: 0 | Z8: =(W8-X8)^2 -> 0 | AA8: =Z8/20 -> 0 | AC8: 5 | AD8: =COUNT(W32:W35) -> 4 | AE8: =SUM(Z32:Z35) -> 1.77 | AF8: =MEDIAN(AG8,AH8) -> 0.47985595 | AG8: 0.41987395 | AH8: 0.53983794 | AI8: =AE8/(2*AD8) -> 0.22125 | AK8: =$AI$19 -> 0.419125 | AL8: =$AI$19*(1-EXP(-(AF8/$AI$20))) -> 0.28546329 | AM8: =$AI$19*(1-EXP(-((AF8)^2/($AI$20)^2))) -> 0.30559731 | AN8: =(AK8-AI8)^2 -> 0.039154516 | AO8: =(AL8-AI8)^2 -> 0.0041233465 | AP8: =(AM8-AI8)^2 -> 0.007114469 | AR8: 5 | AS8: =IF(K8=0,0,IF(K8<=$N$22,$AK$19*(1.5*($K$22/$AK$20)-0.5*($K$22/$AK$20)^3),IF(K8<=$N$23,$AK$19*(1.5*($K$23/$AK$20)-0.5*($K$23/$AK$20)^3),IF(K8<=$N$24,$AK$19*(1.5*($K$24/$AK$20)-0.5*($K$24/$AK$20)^3),IF(K8<=$K$25,$AK$19*(1.5*($K$25/$AK$20)-0.5*($K$25/$AK$20)^3), $AK$19))))) -> 0.419125 | AT8: =IF(L8=0,0,IF(L8<=$N$22,$AK$19*(1.5*($K$22/$AK$20)-0.5*($K$22/$AK$20)^3),IF(L8<=$N$23,$AK$19*(1.5*($K$23/$AK$20)-0.5*($K$23/$AK$20)^3),IF(L8<=$N$24,$AK$19*(1.5*($K$24/$AK$20)-0.5*($K$24/$AK$20)^3),IF(L8<=$K$25,$AK$19*(1.5*($K$25/$AK$20)-0.5*($K$25/$AK$20)^3), $AK$19))))) -> 0.28814844 | AU8: =IF(M8=0,0,IF(M8<=$N$22,$AK$19*(1.5*($K$22/$AK$20)-0.5*($K$22/$AK$20)^3),IF(M8<=$N$23,$AK$19*(1.5*($K$23/$AK$20)-0.5*($K$23/$AK$20)^3),IF(M8<=$N$24,$AK$19*(1.5*($K$24/$AK$20)-0.5*($K$24/$AK$20)^3),IF(M8<=$K$25,$AK$19*(1.5*($K$25/$AK$20)-0.5*($K$25/$AK$20)^3), $AK$19))))) -> 0.38310645 | AV8: =IF(N8=0,0,IF(N8<=$N$22,$AK$19*(1.5*($K$22/$AK$20)-0.5*($K$22/$AK$20)^3),IF(N8<=$N$23,$AK$19*(1.5*($K$23/$AK$20)-0.5*($K$23/$AK$20)^3),IF(N8<=$N$24,$AK$19*(1.5*($K$24/$AK$20)-0.5*($K$24/$AK$20)^3),IF(N8<=$K$25,$AK$19*(1.5*($K$25/$AK$20)-0.5*($K$25/$AK$20)^3), $AK$19))))) -> 0.419125 | AW8: =IF(O8=0,0,IF(O8<=$N$22,$AK$19*(1.5*($K$22/$AK$20)-0.5*($K$22/$AK$20)^3),IF(O8<=$N$23,$AK$19*(1.5*($K$23/$AK$20)-0.5*($K$23/$AK$20)^3),IF(O8<=$N$24,$AK$19*(1.5*($K$24/$AK$20)-0.5*($K$24/$AK$20)^3),IF(O8<=$K$25,$AK$19*(1.5*($K$25/$AK$20)-0.5*($K$25/$AK$20)^3), $AK$19))))) -> 0 | AX8: =IF(P8=0,0,IF(P8<=$N$22,$AK$19*(1.5*($K$22/$AK$20)-0.5*($K$22/$AK$20)^3),IF(P8<=$N$23,$AK$19*(1.5*($K$23/$AK$20)-0.5*($K$23/$AK$20)^3),IF(P8<=$N$24,$AK$19*(1.5*($K$24/$AK$20)-0.5*($K$24/$AK$20)^3),IF(P8<=$K$25,$AK$19*(1.5*($K$25/$AK$20)-0.5*($K$25/$AK$20)^3), $AK$19))))) -> 0.419125 | AY8: =IF(Q8=0,0,IF(Q8<=$N$22,$AK$19*(1.5*($K$22/$AK$20)-0.5*($K$22/$AK$20)^3),IF(Q8<=$N$23,$AK$19*(1.5*($K$23/$AK$20)-0.5*($K$23/$AK$20)^3),IF(Q8<=$N$24,$AK$19*(1.5*($K$24/$AK$20)-0.5*($K$24/$AK$20)^3),IF(Q8<=$K$25,$AK$19*(1.5*($K$25/$AK$20)-0.5*($K$25/$AK$20)^3), $AK$19))))) -> 0.38310645 | AZ8: =IF(R8=0,0,IF(R8<=$N$22,$AK$19*(1.5*($K$22/$AK$20)-0.5*($K$22/$AK$20)^3),IF(R8<=$N$23,$AK$19*(1.5*($K$23/$AK$20)-0.5*($K$23/$AK$20)^3),IF(R8<=$N$24,$AK$19*(1.5*($K$24/$AK$20)-0.5*($K$24/$AK$20)^3),IF(R8<=$K$25,$AK$19*(1.5*($K$25/$AK$20)-0.5*($K$25/$AK$20)^3), $AK$19))))) -> 0.419125 | ... BB8: =IF(T8=0,0,IF(T8<=$N$22,$AK$19*(1.5*($K$22/$AK$20)-0.5*($K$22/$AK$20)^3),IF(T8<=$N$23,$AK$19*(1.5*($K$23/$AK$20)-0.5*($K$23/$AK$20)^3),IF(T8<=$N$24,$AK$19*(1.5*($K$24/$AK$20)-0.5*($K$24/$AK$20)^3),IF(T8<=$K$25,$AK$19*(1.5*($K$25/$AK$20)-0.5*($K$25/$AK$20)^3), $AK$19))))) -> 0.419125 | BD8: 5 | BE8: =IF(U8=0,0,IF(U8<=$N$22,$AK$19*(1.5*($K$22/$AK$20)-0.5*($K$22/$AK$20)^3),IF(U8<=$N$23,$AK$19*(1.5*($K$23/$AK$20)-0.5*($K$23/$AK$20)^3),IF(U8<=$N$24,$AK$19*(1.5*($K$24/$AK$20)-0.5*($K$24/$AK$20)^3),IF(U8<=$K$25,$AK$19*(1.5*($K$25/$AK$20)-0.5*($K$25/$AK$20)^3), $AK$19))))) -> 0.38310645 | BH8: 6 | BI8: 0.0381 | BJ8: =BI8*G10 -> 0.13716 | BK8: =BI8*(G10-$N$15) -> 0.01524
A9: 5 | B9: 44215 | C9: 0.67125 | D9: -7.02 | E9: 106.76 | F9: 10 | G9: 2.2 | I9: 3.6 | J9: 6 | K9: =SQRT(('Olah Semivariogram'!$D$5-'Olah Semivariogram'!D10)^2+('Olah Semivariogram'!$E$5-'Olah Semivariogram'!E10)^2) -> 0.65734314 | L9: =SQRT(('Olah Semivariogram'!$D$6-'Olah Semivariogram'!D10)^2+('Olah Semivariogram'!$E$6-'Olah Semivariogram'!E10)^2) -> 0.73054774 | M9: =SQRT(('Olah Semivariogram'!$D$7-'Olah Semivariogram'!D10)^2+('Olah Semivariogram'!$E$7-'Olah Semivariogram'!E10)^2) -> 1.0796759 | N9: =SQRT(('Olah Semivariogram'!$D$8-'Olah Semivariogram'!D10)^2+('Olah Semivariogram'!$E$8-'Olah Semivariogram'!E10)^2) -> 0.02236068 | O9: =SQRT(('Olah Semivariogram'!$D$9-'Olah Semivariogram'!D10)^2+('Olah Semivariogram'!$E$9-'Olah Semivariogram'!E10)^2) -> 0.95189285 | P9: =SQRT(('Olah Semivariogram'!$D$10-'Olah Semivariogram'!D10)^2+('Olah Semivariogram'!$E$10-'Olah Semivariogram'!E10)^2) -> 0 | Q9: =SQRT(('Olah Semivariogram'!$D$11-'Olah Semivariogram'!D10)^2+('Olah Semivariogram'!$E$11-'Olah Semivariogram'!E10)^2) -> 0.78600254 | R9: =SQRT(('Olah Semivariogram'!$D$12-'Olah Semivariogram'!D10)^2+('Olah Semivariogram'!$E$12-'Olah Semivariogram'!E10)^2) -> 0.74431176 | S9: =SQRT(('Olah Semivariogram'!$D$13-'Olah Semivariogram'!D10)^2+('Olah Semivariogram'!$E$13-'Olah Semivariogram'!E10)^2) -> 0.72964923 | T9: =SQRT(('Olah Semivariogram'!$D$14-'Olah Semivariogram'!D10)^2+('Olah Semivariogram'!$E$14-'Olah Semivariogram'!E10)^2) -> 0.5920304 | U9: =SQRT((D10-$D$15)^2+(E10-$E$15)^2) -> 0.83815273 | W9: 3.6 | X9: 3.6 | Y9: 0 | Z9: =(W9-X9)^2 -> 0 | AA9: =Z9/20 -> 0 | AC9: 6 | AD9: =COUNT(W36:W40) -> 5 | AE9: =SUM(Z36:Z40) -> 2.65 | AF9: =MEDIAN(AG9,AH9) -> 0.59981993 | AG9: 0.53983794 | AH9: 0.65980193 | AI9: =AE9/(2*AD9) -> 0.265 | AK9: =$AI$19 -> 0.419125 | AL9: =$AI$19*(1-EXP(-(AF9/$AI$20))) -> 0.31868126 | AM9: =$AI$19*(1-EXP(-((AF9)^2/($AI$20)^2))) -> 0.36467119 | AN9: =(AK9-AI9)^2 -> 0.023754516 | AO9: =(AL9-AI9)^2 -> 0.0028816776 | AP9: =(AM9-AI9)^2 -> 0.0099343455 | AR9: 6 | AS9: =IF(K9=0,0,IF(K9<=$N$22,$AK$19*(1.5*($K$22/$AK$20)-0.5*($K$22/$AK$20)^3),IF(K9<=$N$23,$AK$19*(1.5*($K$23/$AK$20)-0.5*($K$23/$AK$20)^3),IF(K9<=$N$24,$AK$19*(1.5*($K$24/$AK$20)-0.5*($K$24/$AK$20)^3),IF(K9<=$K$25,$AK$19*(1.5*($K$25/$AK$20)-0.5*($K$25/$AK$20)^3), $AK$19))))) -> 0.419125 | AT9: =IF(L9=0,0,IF(L9<=$N$22,$AK$19*(1.5*($K$22/$AK$20)-0.5*($K$22/$AK$20)^3),IF(L9<=$N$23,$AK$19*(1.5*($K$23/$AK$20)-0.5*($K$23/$AK$20)^3),IF(L9<=$N$24,$AK$19*(1.5*($K$24/$AK$20)-0.5*($K$24/$AK$20)^3),IF(L9<=$K$25,$AK$19*(1.5*($K$25/$AK$20)-0.5*($K$25/$AK$20)^3), $AK$19))))) -> 0.419125 | AU9: =IF(M9=0,0,IF(M9<=$N$22,$AK$19*(1.5*($K$22/$AK$20)-0.5*($K$22/$AK$20)^3),IF(M9<=$N$23,$AK$19*(1.5*($K$23/$AK$20)-0.5*($K$23/$AK$20)^3),IF(M9<=$N$24,$AK$19*(1.5*($K$24/$AK$20)-0.5*($K$24/$AK$20)^3),IF(M9<=$K$25,$AK$19*(1.5*($K$25/$AK$20)-0.5*($K$25/$AK$20)^3), $AK$19))))) -> 0.419125 | AV9: =IF(N9=0,0,IF(N9<=$N$22,$AK$19*(1.5*($K$22/$AK$20)-0.5*($K$22/$AK$20)^3),IF(N9<=$N$23,$AK$19*(1.5*($K$23/$AK$20)-0.5*($K$23/$AK$20)^3),IF(N9<=$N$24,$AK$19*(1.5*($K$24/$AK$20)-0.5*($K$24/$AK$20)^3),IF(N9<=$K$25,$AK$19*(1.5*($K$25/$AK$20)-0.5*($K$25/$AK$20)^3), $AK$19))))) -> 0.15389746 | AW9: =IF(O9=0,0,IF(O9<=$N$22,$AK$19*(1.5*($K$22/$AK$20)-0.5*($K$22/$AK$20)^3),IF(O9<=$N$23,$AK$19*(1.5*($K$23/$AK$20)-0.5*($K$23/$AK$20)^3),IF(O9<=$N$24,$AK$19*(1.5*($K$24/$AK$20)-0.5*($K$24/$AK$20)^3),IF(O9<=$K$25,$AK$19*(1.5*($K$25/$AK$20)-0.5*($K$25/$AK$20)^3), $AK$19))))) -> 0.419125 | AX9: =IF(P9=0,0,IF(P9<=$N$22,$AK$19*(1.5*($K$22/$AK$20)-0.5*($K$22/$AK$20)^3),IF(P9<=$N$23,$AK$19*(1.5*($K$23/$AK$20)-0.5*($K$23/$AK$20)^3),IF(P9<=$N$24,$AK$19*(1.5*($K$24/$AK$20)-0.5*($K$24/$AK$20)^3),IF(P9<=$K$25,$AK$19*(1.5*($K$25/$AK$20)-0.5*($K$25/$AK$20)^3), $AK$19))))) -> 0 | AY9: =IF(Q9=0,0,IF(Q9<=$N$22,$AK$19*(1.5*($K$22/$AK$20)-0.5*($K$22/$AK$20)^3),IF(Q9<=$N$23,$AK$19*(1.5*($K$23/$AK$20)-0.5*($K$23/$AK$20)^3),IF(Q9<=$N$24,$AK$19*(1.5*($K$24/$AK$20)-0.5*($K$24/$AK$20)^3),IF(Q9<=$K$25,$AK$19*(1.5*($K$25/$AK$20)-0.5*($K$25/$AK$20)^3), $AK$19))))) -> 0.419125 | AZ9: =IF(R9=0,0,IF(R9<=$N$22,$AK$19*(1.5*($K$22/$AK$20)-0.5*($K$22/$AK$20)^3),IF(R9<=$N$23,$AK$19*(1.5*($K$23/$AK$20)-0.5*($K$23/$AK$20)^3),IF(R9<=$N$24,$AK$19*(1.5*($K$24/$AK$20)-0.5*($K$24/$AK$20)^3),IF(R9<=$K$25,$AK$19*(1.5*($K$25/$AK$20)-0.5*($K$25/$AK$20)^3), $AK$19))))) -> 0.419125 | ... BB9: =IF(T9=0,0,IF(T9<=$N$22,$AK$19*(1.5*($K$22/$AK$20)-0.5*($K$22/$AK$20)^3),IF(T9<=$N$23,$AK$19*(1.5*($K$23/$AK$20)-0.5*($K$23/$AK$20)^3),IF(T9<=$N$24,$AK$19*(1.5*($K$24/$AK$20)-0.5*($K$24/$AK$20)^3),IF(T9<=$K$25,$AK$19*(1.5*($K$25/$AK$20)-0.5*($K$25/$AK$20)^3), $AK$19))))) -> 0.419125 | BD9: 6 | BE9: =IF(U9=0,0,IF(U9<=$N$22,$AK$19*(1.5*($K$22/$AK$20)-0.5*($K$22/$AK$20)^3),IF(U9<=$N$23,$AK$19*(1.5*($K$23/$AK$20)-0.5*($K$23/$AK$20)^3),IF(U9<=$N$24,$AK$19*(1.5*($K$24/$AK$20)-0.5*($K$24/$AK$20)^3),IF(U9<=$K$25,$AK$19*(1.5*($K$25/$AK$20)-0.5*($K$25/$AK$20)^3), $AK$19))))) -> 0.419125 | BH9: 7 | BI9: 0.5857 | BJ9: =BI9*G11 -> 1.81567 | BK9: =BI9*(G11-$N$15) -> -0.05857
